Workbook

Sheet SKU Master
A1: BU | B1: SKU | C1: Brand | D1: Model | E1: Avg Price
A2: Makeup | B2: M01 | C2: Maybeleen | D2: Compact Powder | E2: 210
A3: Makeup | B3: M02 | C3: Garner | D3: Cleansing Water | E3: 199
A4: Makeup | B4: M03 | C4: Dads Co | D4: UnderEye Cream | E4: 322
A5: Makeup | B5: M04 | C5: Maybeleen | D5: BabyLips | E5: 161
A6: Makeup | B6: M05 | C6: Chakma | D6: Pore Cleanser | E6: 109
A7: Makeup | B7: M06 | C7: Chemitique | D7: Berberry Cleanser | E7: 122
A8: Makeup | B8: M07 | C8: Alps | D8: Aloe Face Wipes | E8: 96
A9: Makeup | B9: M08 | C9: MEGA | D9: Black head remover | E9: 73
A10: Makeup | B10: M09 | C10: Sironah | D10: Face Razor | E10: 225
A11: Makeup | B11: M10 | C11: Bonds | D11: Age Magic | E11: 559
A12: Furniture | B12: F01 | C12: Amazonian Basix | D12: 0 Gravity chair | E12: 3199
A13: Furniture | B13: F02 | C13: ADHD | D13: Wooden Coffee Table | E13: 371
... A31: Luxury | B31: L10 | C31: Schwazkopf | D31: Absolut Repair | E31: 1477

Sheet Open STK
A1: SKU | B1: H | C1: C | D1: M | E1: Total Stock
A2: F01 | B2: 378 | C2: 75 | D2: 44 | E2: =SUM(B2:D2) -> 497
A3: F02 | B3: 187 | C3: 40 | D3: 24 | E3: =SUM(B3:D3) -> 251
A4: F03 | B4: 63 | C4: 34 | D4: 12 | E4: =SUM(B4:D4) -> 109
A5: F04 | B5: 83 | C5: 21 | D5: 14 | E5: =SUM(B5:D5) -> 118
A6: F05 | B6: 86 | C6: 24 | D6: 13 | E6: =SUM(B6:D6) -> 123
A7: F06 | B7: 49 | C7: 14 | D7: 6 | E7: =SUM(B7:D7) -> 69
A8: F07 | B8: 55 | C8: 9 | D8: 10 | E8: =SUM(B8:D8) -> 74
A9: F08 | B9: 23 | C9: 4 | D9: 2 | E9: =SUM(B9:D9) -> 29
A10: F09 | B10: 15 | C10: 5 | D10: 2 | E10: =SUM(B10:D10) -> 22
A11: F10 | B11: 16 | C11: 8 | D11: 2 | E11: =SUM(B11:D11) -> 26
A12: L01 | B12: 234 | C12: 58 | D12: 63 | E12: =SUM(B12:D12) -> 355
A13: L02 | B13: 234 | C13: 32 | D13: 49 | E13: =SUM(B13:D13) -> 315
... A31: M10 | B31: 9 | C31: 3 | D31: 1 | E31: =SUM(B31:D31) -> 13

Sheet Open STK Sorted
A1: SKU | B1: H | C1: C | D1: M | E1: Total Stock
A2: F01 | B2: 378 | C2: 75 | D2: 44 | E2: 497
A3: F02 | B3: 187 | C3: 40 | D3: 24 | E3: 251
A4: F03 | B4: 63 | C4: 34 | D4: 12 | E4: 109
A5: F04 | B5: 83 | C5: 21 | D5: 14 | E5: 118
A6: F05 | B6: 86 | C6: 24 | D6: 13 | E6: 123
A7: F06 | B7: 49 | C7: 14 | D7: 6 | E7: 69
A8: F07 | B8: 55 | C8: 9 | D8: 10 | E8: 74
A9: F08 | B9: 23 | C9: 4 | D9: 2 | E9: 29
A10: F09 | B10: 15 | C10: 5 | D10: 2 | E10: 22
A11: F10 | B11: 16 | C11: 8 | D11: 2 | E11: 26
A12: L01 | B12: 234 | C12: 58 | D12: 63 | E12: 355
A13: L02 | B13: 234 | C13: 32 | D13: 49 | E13: 315
... A31: M10 | B31: 9 | C31: 3 | D31: 1 | E31: 13

Sheet Stock Transfer
A1: STK TRNS | B1: C | Q1: M
A2: SKU | B2: 44287 | C2: 44288 | D2: 44289 | E2: 44290 | F2: 44291 | G2: 44292 | H2: 44293 | I2: 44294 | J2: 44295 | K2: 44296 | L2: 44297 | M2: 44298 | N2: 44299 | O2: 44300 | P2: 44301 | Q2: 44287 | R2: 44288 | S2: 44289 | T2: 44290 | U2: 44291 | V2: 44292 | W2: 44293 | X2: 44294 | Y2: 44295 | Z2: 44296 | AA2: 44297 | AB2: 44298 | AC2: 44299 | AD2: 44300 | AE2: 44301
A3: F01 | B3: 11 | C3: 22 | D3: 16 | E3: 18 | F3: 14 | G3: 20 | H3: 16 | I3: 13 | J3: 17 | K3: 16 | L3: 14 | M3: 9 | N3: 14 | O3: 12 | P3: 20 | Q3: 8 | R3: 10 | S3: 15 | T3: 8 | U3: 13 | V3: 7 | W3: 14 | X3: 11 | Y3: 17 | Z3: 14 | AA3: 19 | AB3: 11 | AC3: 13 | AD3: 12 | AE3: 12
A4: F02 | B4: 6 | C4: 8 | D4: 7 | E4: 10 | F4: 8 | G4: 9 | H4: 8 | I4: 7 | J4: 8 | K4: 10 | L4: 6 | M4: 10 | N4: 7 | O4: 11 | P4: 7 | Q4: 5 | R4: 5 | S4: 8 | T4: 7 | U4: 6 | V4: 7 | W4: 4 | X4: 6 | Y4: 7 | Z4: 5 | AA4: 5 | AB4: 7 | AC4: 4 | AD4: 6 | AE4: 8
A5: F03 | B5: 9 | C5: 7 | D5: 8 | E5: 6 | F5: 6 | G5: 8 | H5: 5 | I5: 6 | J5: 6 | K5: 7 | L5: 5 | M5: 8 | N5: 7 | O5: 7 | P5: 5 | Q5: 6 | R5: 5 | S5: 4 | T5: 4 | U5: 6 | V5: 6 | W5: 5 | X5: 7 | Y5: 6 | Z5: 8 | AA5: 7 | AB5: 4 | AC5: 8 | AD5: 5 | AE5: 7
A6: F04 | B6: 7 | C6: 7 | D6: 7 | E6: 5 | F6: 7 | G6: 5 | H6: 7 | I6: 5 | J6: 4 | K6: 6 | L6: 5 | M6: 5 | N6: 5 | O6: 5 | P6: 4 | Q6: 3 | R6: 4 | S6: 4 | T6: 3 | U6: 4 | V6: 4 | W6: 4 | X6: 5 | Y6: 4 | Z6: 4 | AA6: 6 | AB6: 5 | AC6: 7 | AD6: 5 | AE6: 7
A7: F05 | B7: 4 | C7: 6 | D7: 5 | E7: 5 | F7: 4 | G7: 3 | H7: 5 | I7: 5 | J7: 6 | K7: 6 | L7: 5 | M7: 5 | N7: 5 | O7: 4 | P7: 5 | Q7: 4 | R7: 4 | S7: 4 | T7: 3 | U7: 3 | V7: 3 | W7: 4 | X7: 3 | Y7: 3 | Z7: 2 | AA7: 3 | AB7: 2 | AC7: 2 | AD7: 3 | AE7: 3
A8: F06 | B8: 4 | C8: 5 | D8: 4 | E8: 4 | F8: 4 | G8: 3 | H8: 5 | I8: 3 | J8: 4 | K8: 4 | L8: 4 | M8: 3 | N8: 4 | O8: 4 | P8: 3 | Q8: 3 | R8: 3 | S8: 2 | T8: 3 | U8: 2 | V8: 3 | W8: 3 | X8: 3 | Y8: 3 | Z8: 2 | AA8: 3 | AB8: 3 | AC8: 2 | AD8: 3 | AE8: 2
A9: F07 | B9: 3 | C9: 3 | D9: 4 | E9: 3 | F9: 3 | G9: 3 | H9: 3 | I9: 3 | J9: 3 | K9: 4 | L9: 3 | M9: 4 | N9: 4 | O9: 3 | P9: 4 | Q9: 3 | R9: 3 | S9: 4 | T9: 3 | U9: 3 | V9: 3 | W9: 2 | X9: 3 | Y9: 3 | Z9: 2 | AA9: 2 | AB9: 3 | AC9: 3 | AD9: 2 | AE9: 2
A10: F08 | B10: 3 | C10: 2 | D10: 2 | E10: 2 | F10: 3 | G10: 2 | H10: 3 | I10: 3 | J10: 3 | K10: 3 | L10: 3 | M10: 3 | N10: 3 | O10: 3 | P10: 3 | Q10: 2 | R10: 2 | S10: 2 | T10: 2 | U10: 2 | V10: 2 | W10: 2 | X10: 2 | Y10: 2 | Z10: 2 | AA10: 2 | AB10: 2 | AC10: 2 | AD10: 2 | AE10: 2
A11: F09 | B11: 2 | C11: 3 | D11: 3 | E11: 3 | F11: 2 | G11: 2 | H11: 3 | I11: 3 | J11: 2 | K11: 3 | L11: 3 | M11: 3 | N11: 3 | O11: 3 | P11: 3 | Q11: 2 | R11: 2 | S11: 2 | T11: 2 | U11: 2 | V11: 2 | W11: 2 | X11: 2 | Y11: 2 | Z11: 2 | AA11: 2 | AB11: 2 | AC11: 2 | AD11: 2 | AE11: 2
A12: F10 | B12: 3 | C12: 3 | D12: 3 | E12: 3 | F12: 3 | G12: 3 | H12: 3 | I12: 2 | J12: 2 | K12: 2 | L12: 3 | M12: 4 | N12: 3 | O12: 4 | P12: 3 | Q12: 2 | R12: 2 | S12: 2 | T12: 2 | U12: 2 | V12: 2 | W12: 2 | X12: 2 | Y12: 2 | Z12: 2 | AA12: 2 | AB12: 2 | AC12: 2 | AD12: 2 | AE12: 2
A13: L01 | B13: 10 | C13: 8 | D13: 12 | E13: 7 | F13: 13 | G13: 7 | H13: 13 | I13: 11 | J13: 11 | K13: 11 | L13: 6 | M13: 11 | N13: 11 | O13: 8 | P13: 7 | Q13: 22 | R13: 13 | S13: 13 | T13: 21 | U13: 21 | V13: 21 | W13: 14 | X13: 13 | Y13: 22 | Z13: 17 | AA13: 22 | AB13: 14 | AC13: 15 | AD13: 18 | AE13: 16
... A32: M10 | B32: 3 | C32: 3 | D32: 2 | E32: 2 | F32: 2 | G32: 2 | H32: 3 | I32: 2 | J32: 2 | K32: 3 | L32: 2 | M32: 2 | N32: 2 | O32: 2 | P32: 2 | Q32: 2 | R32: 2 | S32: 2 | T32: 2 | U32: 2 | V32: 2 | W32: 2 | X32: 2 | Y32: 2 | Z32: 2 | AA32: 2 | AB32: 2 | AC32: 2 | AD32: 2 | AE32: 2

Sheet Pivot Table
A1: SKU | B1: M10
A2: City | B2: M
F3: Average | H3: =B22 -> 0.26666667
A4: Row Labels | B4: Sum of Sales | F4: Total Open STK | H4: =VLOOKUP(B1,'Open STK Sorted'!A1:E31,5,0) -> 13
A5: 44287 | B5: 0 | F5: Days of inventory (Days of Cover) | H5: =H4/H3 -> 48.75
A6: 44288 | B6: 0
A7: 44289 | B7: 0 | F7: Madras DC | G7: Open STK | H7: Total Sales | I7: Avg Sales | J7: Cover Days | L7: Max
A8: 44290 | B8: 0 | F8: F01 | G8: 44 | H8: 210 | I8: =H8/15 -> 14 | J8: =G8/I8 -> 3.1428571 | L8: =MAX(J8:J37) -> 15
A9: 44291 | B9: 1 | F9: F02 | G9: 24 | H9: 87 | I9: =H9/15 -> 5.8 | J9: =G9/I9 -> 4.137931
A10: 44292 | B10: 1 | F10: F03 | G10: 12 | H10: 76 | I10: =H10/15 -> 5.0666667 | J10: =G10/I10 -> 2.3684211
A11: 44293 | B11: 0 | F11: F04 | G11: 14 | H11: 59 | I11: =H11/15 -> 3.9333333 | J11: =G11/I11 -> 3.559322
A12: 44294 | B12: 0 | F12: F05 | G12: 13 | H12: 32 | I12: =H12/15 -> 2.1333333 | J12: =G12/I12 -> 6.09375
A13: 44295 | B13: 0 | F13: F06 | G13: 6 | H13: 21 | I13: =H13/15 -> 1.4 | J13: =G13/I13 -> 4.2857143
A14: 44296 | B14: 0 | F14: F07 | G14: 10 | H14: 26 | I14: =H14/15 -> 1.7333333 | J14: =G14/I14 -> 5.7692308
A15: 44297 | B15: 0 | F15: F08 | G15: 2 | H15: 6 | I15: =H15/15 -> 0.4 | J15: =G15/I15 -> 5
A16: 44298 | B16: 1 | F16: F09 | G16: 2 | H16: 3 | I16: =H16/15 -> 0.2 | J16: =G16/I16 -> 10
A17: 44299 | B17: 1 | F17: F10 | G17: 2 | H17: 4 | I17: =H17/15 -> 0.26666667 | J17: =G17/I17 -> 7.5
A18: 44300 | B18: 0 | F18: L01 | G18: 63 | H18: 301 | I18: =H18/15 -> 20.066667 | J18: =G18/I18 -> 3.1395349
A19: 44301 | B19: 0 | F19: L02 | G19: 49 | H19: 149 | I19: =H19/15 -> 9.9333333 | J19: =G19/I19 -> 4.9328859
A20: Grand Total | B20: 4 | F20: L03 | G20: 23 | H20: 109 | I20: =H20/15 -> 7.2666667 | J20: =G20/I20 -> 3.1651376
F21: L04 | G21: 23 | H21: 85 | I21: =H21/15 -> 5.6666667 | J21: =G21/I21 -> 4.0588235
A22: Average | B22: =GETPIVOTDATA("Sales",$A$4)/15 -> 0.26666667 | F22: L05 | G22: 13 | H22: 42 | I22: =H22/15 -> 2.8 | J22: =G22/I22 -> 4.6428571
F23: L06 | G23: 6 | H23: 18 | I23: =H23/15 -> 1.2 | J23: =G23/I23 -> 5
F24: L07 | G24: 3 | H24: 8 | I24: =H24/15 -> 0.53333333 | J24: =G24/I24 -> 5.625
F25: L08 | G25: 2 | H25: 5 | I25: =H25/15 -> 0.33333333 | J25: =G25/I25 -> 6
F26: L09 | G26: 1 | H26: 1 | I26: =H26/15 -> 0.066666667 | J26: =G26/I26 -> 15
F27: L10 | G27: 2 | H27: 4 | I27: =H27/15 -> 0.26666667 | J27: =G27/I27 -> 7.5
F28: M01 | G28: 60 | H28: 317 | I28: =H28/15 -> 21.133333 | J28: =G28/I28 -> 2.8391167
F29: M02 | G29: 33 | H29: 154 | I29: =H29/15 -> 10.266667 | J29: =G29/I29 -> 3.2142857
F30: M03 | G30: 18 | H30: 115 | I30: =H30/15 -> 7.6666667 | J30: =G30/I30 -> 2.3478261
F31: M04 | G31: 14 | H31: 87 | I31: =H31/15 -> 5.8 | J31: =G31/I31 -> 2.4137931
F32: M05 | G32: 9 | H32: 58 | I32: =H32/15 -> 3.8666667 | J32: =G32/I32 -> 2.3275862
F33: M06 | G33: 7 | H33: 37 | I33: =H33/15 -> 2.4666667 | J33: =G33/I33 -> 2.8378378
F34: M07 | G34: 9 | H34: 36 | I34: =H34/15 -> 2.4 | J34: =G34/I34 -> 3.75
... F37: M10 | G37: 1 | H37: 4 | I37: =H37/15 -> 0.26666667 | J37: =G37/I37 -> 3.75

Sheet Madras Ledger
C1: 1 | G1: =C1+1 -> 2 | K1: =G1+1 -> 3 | O1: =K1+1 -> 4 | S1: =O1+1 -> 5 | W1: =S1+1 -> 6 | AA1: =W1+1 -> 7 | AE1: =AA1+1 -> 8 | AI1: =AE1+1 -> 9 | AM1: =AI1+1 -> 10
B2: =DATE(2021,4,C1) -> 44287 | F2: =DATE(2021,4,G1) -> 44288 | J2: =DATE(2021,4,K1) -> 44289 | N2: =DATE(2021,4,O1) -> 44290 | R2: =DATE(2021,4,S1) -> 44291 | V2: =DATE(2021,4,W1) -> 44292 | Z2: =DATE(2021,4,AA1) -> 44293 | AD2: =DATE(2021,4,AE1) -> 44294 | AH2: =DATE(2021,4,AI1) -> 44295 | AL2: =DATE(2021,4,AM1) -> 44296
A3: SKU | B3: Open Stock | C3: Sales | D3: Incoming | E3: Closing Stock | F3: Open Stock | G3: Sales | H3: Incoming | I3: Closing Stock | J3: Open Stock | K3: Sales | L3: Incoming | M3: Closing Stock | N3: Open Stock | O3: Sales | P3: Incoming | Q3: Closing Stock | R3: Open Stock | S3: Sales | T3: Incoming | U3: Closing Stock | V3: Open Stock | W3: Sales | X3: Incoming | Y3: Closing Stock | Z3: Open Stock | AA3: Sales | AB3: Incoming | AC3: Closing Stock | AD3: Open Stock | AE3: Sales | AF3: Incoming | AG3: Closing Stock | AH3: Open Stock | AI3: Sales | AJ3: Incoming | AK3: Closing Stock | AL3: Open Stock | AM3: Sales | AN3: Incoming | AO3: Closing Stock
A4: F01 | B4: =VLOOKUP($A4,'Open STK'!$A$1:$E$31,4,0) -> 44 | C4: =VLOOKUP($A4,'Madras Sales'!$A$4:$P$35,C$1+1,0) -> 14 | D4: =VLOOKUP($A4,'Stock Transfer'!$A$3:$AE$32,16+C$1,0) -> 8 | E4: =B4-C4+D4 -> 38 | F4: =MAX(E4,0) -> 38 | G4: =VLOOKUP($A4,'Madras Sales'!$A$4:$P$35,G$1+1,0) -> 9 | H4: =VLOOKUP($A4,'Stock Transfer'!$A$3:$AE$32,16+G$1,0) -> 10 | I4: =F4-G4+H4 -> 39 | J4: =MAX(I4,0) -> 39 | K4: =VLOOKUP($A4,'Madras Sales'!$A$4:$P$35,K$1+1,0) -> 13 | L4: =VLOOKUP($A4,'Stock Transfer'!$A$3:$AE$32,16+K$1,0) -> 15 | M4: =J4-K4+L4 -> 41 | N4: =MAX(M4,0) -> 41 | O4: =VLOOKUP($A4,'Madras Sales'!$A$4:$P$35,O$1+1,0) -> 6 | P4: =VLOOKUP($A4,'Stock Transfer'!$A$3:$AE$32,16+O$1,0) -> 8 | Q4: =N4-O4+P4 -> 43 | R4: =MAX(Q4,0) -> 43 | S4: =VLOOKUP($A4,'Madras Sales'!$A$4:$P$35,S$1+1,0) -> 21 | T4: =VLOOKUP($A4,'Stock Transfer'!$A$3:$AE$32,16+S$1,0) -> 13 | U4: =R4-S4+T4 -> 35 | V4: =MAX(U4,0) -> 35 | W4: =VLOOKUP($A4,'Madras Sales'!$A$4:$P$35,W$1+1,0) -> 18 | X4: =VLOOKUP($A4,'Stock Transfer'!$A$3:$AE$32,16+W$1,0) -> 7 | Y4: =V4-W4+X4 -> 24 | Z4: =MAX(Y4,0) -> 24 | AA4: =VLOOKUP($A4,'Madras Sales'!$A$4:$P$35,AA$1+1,0) -> 2 | AB4: =VLOOKUP($A4,'Stock Transfer'!$A$3:$AE$32,16+AA$1,0) -> 14 | AC4: =Z4-AA4+AB4 -> 36 | AD4: =MAX(AC4,0) -> 36 | AE4: =VLOOKUP($A4,'Madras Sales'!$A$4:$P$35,AE$1+1,0) -> 24 | AF4: =VLOOKUP($A4,'Stock Transfer'!$A$3:$AE$32,16+AE$1,0) -> 11 | AG4: =AD4-AE4+AF4 -> 23 | AH4: =MAX(AG4,0) -> 23 | AI4: =VLOOKUP($A4,'Madras Sales'!$A$4:$P$35,AI$1+1,0) -> 5 | AJ4: =VLOOKUP($A4,'Stock Transfer'!$A$3:$AE$32,16+AI$1,0) -> 17 | AK4: =AH4-AI4+AJ4 -> 35 | AL4: =MAX(AK4,0) -> 35 | AM4: =VLOOKUP($A4,'Madras Sales'!$A$4:$P$35,AM$1+1,0) -> 13 | AN4: =VLOOKUP($A4,'Stock Transfer'!$A$3:$AE$32,16+AM$1,0) -> 14 | AO4: =AL4-AM4+AN4 -> 36
A5: F02 | B5: =VLOOKUP($A5,'Open STK'!$A$1:$E$31,4,0) -> 24 | C5: =VLOOKUP($A5,'Madras Sales'!$A$4:$P$35,C$1+1,0) -> 13 | D5: =VLOOKUP($A5,'Stock Transfer'!$A$3:$AE$32,16+C$1,0) -> 5 | E5: =B5-C5+D5 -> 16 | F5: =MAX(E5,0) -> 16 | G5: =VLOOKUP($A5,'Madras Sales'!$A$4:$P$35,G$1+1,0) -> 5 | H5: =VLOOKUP($A5,'Stock Transfer'!$A$3:$AE$32,16+G$1,0) -> 5 | I5: =F5-G5+H5 -> 16 | J5: =MAX(I5,0) -> 16 | K5: =VLOOKUP($A5,'Madras Sales'!$A$4:$P$35,K$1+1,0) -> 4 | L5: =VLOOKUP($A5,'Stock Transfer'!$A$3:$AE$32,16+K$1,0) -> 8 | M5: =J5-K5+L5 -> 20 | N5: =MAX(M5,0) -> 20 | O5: =VLOOKUP($A5,'Madras Sales'!$A$4:$P$35,O$1+1,0) -> 2 | P5: =VLOOKUP($A5,'Stock Transfer'!$A$3:$AE$32,16+O$1,0) -> 7 | Q5: =N5-O5+P5 -> 25 | R5: =MAX(Q5,0) -> 25 | S5: =VLOOKUP($A5,'Madras Sales'!$A$4:$P$35,S$1+1,0) -> 7 | T5: =VLOOKUP($A5,'Stock Transfer'!$A$3:$AE$32,16+S$1,0) -> 6 | U5: =R5-S5+T5 -> 24 | V5: =MAX(U5,0) -> 24 | W5: =VLOOKUP($A5,'Madras Sales'!$A$4:$P$35,W$1+1,0) -> 3 | X5: =VLOOKUP($A5,'Stock Transfer'!$A$3:$AE$32,16+W$1,0) -> 7 | Y5: =V5-W5+X5 -> 28 | Z5: =MAX(Y5,0) -> 28 | AA5: =VLOOKUP($A5,'Madras Sales'!$A$4:$P$35,AA$1+1,0) -> 7 | AB5: =VLOOKUP($A5,'Stock Transfer'!$A$3:$AE$32,16+AA$1,0) -> 4 | AC5: =Z5-AA5+AB5 -> 25 | AD5: =MAX(AC5,0) -> 25 | AE5: =VLOOKUP($A5,'Madras Sales'!$A$4:$P$35,AE$1+1,0) -> 3 | AF5: =VLOOKUP($A5,'Stock Transfer'!$A$3:$AE$32,16+AE$1,0) -> 6 | AG5: =AD5-AE5+AF5 -> 28 | AH5: =MAX(AG5,0) -> 28 | AI5: =VLOOKUP($A5,'Madras Sales'!$A$4:$P$35,AI$1+1,0) -> 1 | AJ5: =VLOOKUP($A5,'Stock Transfer'!$A$3:$AE$32,16+AI$1,0) -> 7 | AK5: =AH5-AI5+AJ5 -> 34 | AL5: =MAX(AK5,0) -> 34 | AM5: =VLOOKUP($A5,'Madras Sales'!$A$4:$P$35,AM$1+1,0) -> 3 | AN5: =VLOOKUP($A5,'Stock Transfer'!$A$3:$AE$32,16+AM$1,0) -> 5 | AO5: =AL5-AM5+AN5 -> 36
A6: F03 | B6: =VLOOKUP($A6,'Open STK'!$A$1:$E$31,4,0) -> 12 | C6: =VLOOKUP($A6,'Madras Sales'!$A$4:$P$35,C$1+1,0) -> 8 | D6: =VLOOKUP($A6,'Stock Transfer'!$A$3:$AE$32,16+C$1,0) -> 6 | E6: =B6-C6+D6 -> 10 | F6: =MAX(E6,0) -> 10 | G6: =VLOOKUP($A6,'Madras Sales'!$A$4:$P$35,G$1+1,0) -> 5 | H6: =VLOOKUP($A6,'Stock Transfer'!$A$3:$AE$32,16+G$1,0) -> 5 | I6: =F6-G6+H6 -> 10 | J6: =MAX(I6,0) -> 10 | K6: =VLOOKUP($A6,'Madras Sales'!$A$4:$P$35,K$1+1,0) -> 7 | L6: =VLOOKUP($A6,'Stock Transfer'!$A$3:$AE$32,16+K$1,0) -> 4 | M6: =J6-K6+L6 -> 7 | N6: =MAX(M6,0) -> 7 | O6: =VLOOKUP($A6,'Madras Sales'!$A$4:$P$35,O$1+1,0) -> 0 | P6: =VLOOKUP($A6,'Stock Transfer'!$A$3:$AE$32,16+O$1,0) -> 4 | Q6: =N6-O6+P6 -> 11 | R6: =MAX(Q6,0) -> 11 | S6: =VLOOKUP($A6,'Madras Sales'!$A$4:$P$35,S$1+1,0) -> 0 | T6: =VLOOKUP($A6,'Stock Transfer'!$A$3:$AE$32,16+S$1,0) -> 6 | U6: =R6-S6+T6 -> 17 | V6: =MAX(U6,0) -> 17 | W6: =VLOOKUP($A6,'Madras Sales'!$A$4:$P$35,W$1+1,0) -> 6 | X6: =VLOOKUP($A6,'Stock Transfer'!$A$3:$AE$32,16+W$1,0) -> 6 | Y6: =V6-W6+X6 -> 17 | Z6: =MAX(Y6,0) -> 17 | AA6: =VLOOKUP($A6,'Madras Sales'!$A$4:$P$35,AA$1+1,0) -> 5 | AB6: =VLOOKUP($A6,'Stock Transfer'!$A$3:$AE$32,16+AA$1,0) -> 5 | AC6: =Z6-AA6+AB6 -> 17 | AD6: =MAX(AC6,0) -> 17 | AE6: =VLOOKUP($A6,'Madras Sales'!$A$4:$P$35,AE$1+1,0) -> 0 | AF6: =VLOOKUP($A6,'Stock Transfer'!$A$3:$AE$32,16+AE$1,0) -> 7 | AG6: =AD6-AE6+AF6 -> 24 | AH6: =MAX(AG6,0) -> 24 | AI6: =VLOOKUP($A6,'Madras Sales'!$A$4:$P$35,AI$1+1,0) -> 4 | AJ6: =VLOOKUP($A6,'Stock Transfer'!$A$3:$AE$32,16+AI$1,0) -> 6 | AK6: =AH6-AI6+AJ6 -> 26 | AL6: =MAX(AK6,0) -> 26 | AM6: =VLOOKUP($A6,'Madras Sales'!$A$4:$P$35,AM$1+1,0) -> 1 | AN6: =VLOOKUP($A6,'Stock Transfer'!$A$3:$AE$32,16+AM$1,0) -> 8 | AO6: =AL6-AM6+AN6 -> 33
A7: F04 | B7: =VLOOKUP($A7,'Open STK'!$A$1:$E$31,4,0) -> 14 | C7: =VLOOKUP($A7,'Madras Sales'!$A$4:$P$35,C$1+1,0) -> 1 | D7: =VLOOKUP($A7,'Stock Transfer'!$A$3:$AE$32,16+C$1,0) -> 3 | E7: =B7-C7+D7 -> 16 | F7: =MAX(E7,0) -> 16 | G7: =VLOOKUP($A7,'Madras Sales'!$A$4:$P$35,G$1+1,0) -> 1 | H7: =VLOOKUP($A7,'Stock Transfer'!$A$3:$AE$32,16+G$1,0) -> 4 | I7: =F7-G7+H7 -> 19 | J7: =MAX(I7,0) -> 19 | K7: =VLOOKUP($A7,'Madras Sales'!$A$4:$P$35,K$1+1,0) -> 3 | L7: =VLOOKUP($A7,'Stock Transfer'!$A$3:$AE$32,16+K$1,0) -> 4 | M7: =J7-K7+L7 -> 20 | N7: =MAX(M7,0) -> 20 | O7: =VLOOKUP($A7,'Madras Sales'!$A$4:$P$35,O$1+1,0) -> 2 | P7: =VLOOKUP($A7,'Stock Transfer'!$A$3:$AE$32,16+O$1,0) -> 3 | Q7: =N7-O7+P7 -> 21 | R7: =MAX(Q7,0) -> 21 | S7: =VLOOKUP($A7,'Madras Sales'!$A$4:$P$35,S$1+1,0) -> 1 | T7: =VLOOKUP($A7,'Stock Transfer'!$A$3:$AE$32,16+S$1,0) -> 4 | U7: =R7-S7+T7 -> 24 | V7: =MAX(U7,0) -> 24 | W7: =VLOOKUP($A7,'Madras Sales'!$A$4:$P$35,W$1+1,0) -> 7 | X7: =VLOOKUP($A7,'Stock Transfer'!$A$3:$AE$32,16+W$1,0) -> 4 | Y7: =V7-W7+X7 -> 21 | Z7: =MAX(Y7,0) -> 21 | AA7: =VLOOKUP($A7,'Madras Sales'!$A$4:$P$35,AA$1+1,0) -> 2 | AB7: =VLOOKUP($A7,'Stock Transfer'!$A$3:$AE$32,16+AA$1,0) -> 4 | AC7: =Z7-AA7+AB7 -> 23 | AD7: =MAX(AC7,0) -> 23 | AE7: =VLOOKUP($A7,'Madras Sales'!$A$4:$P$35,AE$1+1,0) -> 7 | AF7: =VLOOKUP($A7,'Stock Transfer'!$A$3:$AE$32,16+AE$1,0) -> 5 | AG7: =AD7-AE7+AF7 -> 21 | AH7: =MAX(AG7,0) -> 21 | AI7: =VLOOKUP($A7,'Madras Sales'!$A$4:$P$35,AI$1+1,0) -> 6 | AJ7: =VLOOKUP($A7,'Stock Transfer'!$A$3:$AE$32,16+AI$1,0) -> 4 | AK7: =AH7-AI7+AJ7 -> 19 | AL7: =MAX(AK7,0) -> 19 | AM7: =VLOOKUP($A7,'Madras Sales'!$A$4:$P$35,AM$1+1,0) -> 6 | AN7: =VLOOKUP($A7,'Stock Transfer'!$A$3:$AE$32,16+AM$1,0) -> 4 | AO7: =AL7-AM7+AN7 -> 17
A8: F05 | B8: =VLOOKUP($A8,'Open STK'!$A$1:$E$31,4,0) -> 13 | C8: =VLOOKUP($A8,'Madras Sales'!$A$4:$P$35,C$1+1,0) -> 2 | D8: =VLOOKUP($A8,'Stock Transfer'!$A$3:$AE$32,16+C$1,0) -> 4 | E8: =B8-C8+D8 -> 15 | F8: =MAX(E8,0) -> 15 | G8: =VLOOKUP($A8,'Madras Sales'!$A$4:$P$35,G$1+1,0) -> 0 | H8: =VLOOKUP($A8,'Stock Transfer'!$A$3:$AE$32,16+G$1,0) -> 4 | I8: =F8-G8+H8 -> 19 | J8: =MAX(I8,0) -> 19 | K8: =VLOOKUP($A8,'Madras Sales'!$A$4:$P$35,K$1+1,0) -> 0 | L8: =VLOOKUP($A8,'Stock Transfer'!$A$3:$AE$32,16+K$1,0) -> 4 | M8: =J8-K8+L8 -> 23 | N8: =MAX(M8,0) -> 23 | O8: =VLOOKUP($A8,'Madras Sales'!$A$4:$P$35,O$1+1,0) -> 4 | P8: =VLOOKUP($A8,'Stock Transfer'!$A$3:$AE$32,16+O$1,0) -> 3 | Q8: =N8-O8+P8 -> 22 | R8: =MAX(Q8,0) -> 22 | S8: =VLOOKUP($A8,'Madras Sales'!$A$4:$P$35,S$1+1,0) -> 3 | T8: =VLOOKUP($A8,'Stock Transfer'!$A$3:$AE$32,16+S$1,0) -> 3 | U8: =R8-S8+T8 -> 22 | V8: =MAX(U8,0) -> 22 | W8: =VLOOKUP($A8,'Madras Sales'!$A$4:$P$35,W$1+1,0) -> 7 | X8: =VLOOKUP($A8,'Stock Transfer'!$A$3:$AE$32,16+W$1,0) -> 3 | Y8: =V8-W8+X8 -> 18 | Z8: =MAX(Y8,0) -> 18 | AA8: =VLOOKUP($A8,'Madras Sales'!$A$4:$P$35,AA$1+1,0) -> 4 | AB8: =VLOOKUP($A8,'Stock Transfer'!$A$3:$AE$32,16+AA$1,0) -> 4 | AC8: =Z8-AA8+AB8 -> 18 | AD8: =MAX(AC8,0) -> 18 | AE8: =VLOOKUP($A8,'Madras Sales'!$A$4:$P$35,AE$1+1,0) -> 2 | AF8: =VLOOKUP($A8,'Stock Transfer'!$A$3:$AE$32,16+AE$1,0) -> 3 | AG8: =AD8-AE8+AF8 -> 19 | AH8: =MAX(AG8,0) -> 19 | AI8: =VLOOKUP($A8,'Madras Sales'!$A$4:$P$35,AI$1+1,0) -> 0 | AJ8: =VLOOKUP($A8,'Stock Transfer'!$A$3:$AE$32,16+AI$1,0) -> 3 | AK8: =AH8-AI8+AJ8 -> 22 | AL8: =MAX(AK8,0) -> 22 | AM8: =VLOOKUP($A8,'Madras Sales'!$A$4:$P$35,AM$1+1,0) -> 3 | AN8: =VLOOKUP($A8,'Stock Transfer'!$A$3:$AE$32,16+AM$1,0) -> 2 | AO8: =AL8-AM8+AN8 -> 21
A9: F06 | B9: =VLOOKUP($A9,'Open STK'!$A$1:$E$31,4,0) -> 6 | C9: =VLOOKUP($A9,'Madras Sales'!$A$4:$P$35,C$1+1,0) -> 0 | D9: =VLOOKUP($A9,'Stock Transfer'!$A$3:$AE$32,16+C$1,0) -> 3 | E9: =B9-C9+D9 -> 9 | F9: =MAX(E9,0) -> 9 | G9: =VLOOKUP($A9,'Madras Sales'!$A$4:$P$35,G$1+1,0) -> 3 | H9: =VLOOKUP($A9,'Stock Transfer'!$A$3:$AE$32,16+G$1,0) -> 3 | I9: =F9-G9+H9 -> 9 | J9: =MAX(I9,0) -> 9 | K9: =VLOOKUP($A9,'Madras Sales'!$A$4:$P$35,K$1+1,0) -> 0 | L9: =VLOOKUP($A9,'Stock Transfer'!$A$3:$AE$32,16+K$1,0) -> 2 | M9: =J9-K9+L9 -> 11 | N9: =MAX(M9,0) -> 11 | O9: =VLOOKUP($A9,'Madras Sales'!$A$4:$P$35,O$1+1,0) -> 2 | P9: =VLOOKUP($A9,'Stock Transfer'!$A$3:$AE$32,16+O$1,0) -> 3 | Q9: =N9-O9+P9 -> 12 | R9: =MAX(Q9,0) -> 12 | S9: =VLOOKUP($A9,'Madras Sales'!$A$4:$P$35,S$1+1,0) -> 1 | T9: =VLOOKUP($A9,'Stock Transfer'!$A$3:$AE$32,16+S$1,0) -> 2 | U9: =R9-S9+T9 -> 13 | V9: =MAX(U9,0) -> 13 | W9: =VLOOKUP($A9,'Madras Sales'!$A$4:$P$35,W$1+1,0) -> 1 | X9: =VLOOKUP($A9,'Stock Transfer'!$A$3:$AE$32,16+W$1,0) -> 3 | Y9: =V9-W9+X9 -> 15 | Z9: =MAX(Y9,0) -> 15 | AA9: =VLOOKUP($A9,'Madras Sales'!$A$4:$P$35,AA$1+1,0) -> 2 | AB9: =VLOOKUP($A9,'Stock Transfer'!$A$3:$AE$32,16+AA$1,0) -> 3 | AC9: =Z9-AA9+AB9 -> 16 | AD9: =MAX(AC9,0) -> 16 | AE9: =VLOOKUP($A9,'Madras Sales'!$A$4:$P$35,AE$1+1,0) -> 0 | AF9: =VLOOKUP($A9,'Stock Transfer'!$A$3:$AE$32,16+AE$1,0) -> 3 | AG9: =AD9-AE9+AF9 -> 19 | AH9: =MAX(AG9,0) -> 19 | AI9: =VLOOKUP($A9,'Madras Sales'!$A$4:$P$35,AI$1+1,0) -> 3 | AJ9: =VLOOKUP($A9,'Stock Transfer'!$A$3:$AE$32,16+AI$1,0) -> 3 | AK9: =AH9-AI9+AJ9 -> 19 | AL9: =MAX(AK9,0) -> 19 | AM9: =VLOOKUP($A9,'Madras Sales'!$A$4:$P$35,AM$1+1,0) -> 1 | AN9: =VLOOKUP($A9,'Stock Transfer'!$A$3:$AE$32,16+AM$1,0) -> 2 | AO9: =AL9-AM9+AN9 -> 20
A10: F07 | B10: =VLOOKUP($A10,'Open STK'!$A$1:$E$31,4,0) -> 10 | C10: =VLOOKUP($A10,'Madras Sales'!$A$4:$P$35,C$1+1,0) -> 4 | D10: =VLOOKUP($A10,'Stock Transfer'!$A$3:$AE$32,16+C$1,0) -> 3 | E10: =B10-C10+D10 -> 9 | F10: =MAX(E10,0) -> 9 | G10: =VLOOKUP($A10,'Madras Sales'!$A$4:$P$35,G$1+1,0) -> 1 | H10: =VLOOKUP($A10,'Stock Transfer'!$A$3:$AE$32,16+G$1,0) -> 3 | I10: =F10-G10+H10 -> 11 | J10: =MAX(I10,0) -> 11 | K10: =VLOOKUP($A10,'Madras Sales'!$A$4:$P$35,K$1+1,0) -> 1 | L10: =VLOOKUP($A10,'Stock Transfer'!$A$3:$AE$32,16+K$1,0) -> 4 | M10: =J10-K10+L10 -> 14 | N10: =MAX(M10,0) -> 14 | O10: =VLOOKUP($A10,'Madras Sales'!$A$4:$P$35,O$1+1,0) -> 0 | P10: =VLOOKUP($A10,'Stock Transfer'!$A$3:$AE$32,16+O$1,0) -> 3 | Q10: =N10-O10+P10 -> 17 | R10: =MAX(Q10,0) -> 17 | S10: =VLOOKUP($A10,'Madras Sales'!$A$4:$P$35,S$1+1,0) -> 1 | T10: =VLOOKUP($A10,'Stock Transfer'!$A$3:$AE$32,16+S$1,0) -> 3 | U10: =R10-S10+T10 -> 19 | V10: =MAX(U10,0) -> 19 | W10: =VLOOKUP($A10,'Madras Sales'!$A$4:$P$35,W$1+1,0) -> 3 | X10: =VLOOKUP($A10,'Stock Transfer'!$A$3:$AE$32,16+W$1,0) -> 3 | Y10: =V10-W10+X10 -> 19 | Z10: =MAX(Y10,0) -> 19 | AA10: =VLOOKUP($A10,'Madras Sales'!$A$4:$P$35,AA$1+1,0) -> 4 | AB10: =VLOOKUP($A10,'Stock Transfer'!$A$3:$AE$32,16+AA$1,0) -> 2 | AC10: =Z10-AA10+AB10 -> 17 | AD10: =MAX(AC10,0) -> 17 | AE10: =VLOOKUP($A10,'Madras Sales'!$A$4:$P$35,AE$1+1,0) -> 2 | AF10: =VLOOKUP($A10,'Stock Transfer'!$A$3:$AE$32,16+AE$1,0) -> 3 | AG10: =AD10-AE10+AF10 -> 18 | AH10: =MAX(AG10,0) -> 18 | AI10: =VLOOKUP($A10,'Madras Sales'!$A$4:$P$35,AI$1+1,0) -> 1 | AJ10: =VLOOKUP($A10,'Stock Transfer'!$A$3:$AE$32,16+AI$1,0) -> 3 | AK10: =AH10-AI10+AJ10 -> 20 | AL10: =MAX(AK10,0) -> 20 | AM10: =VLOOKUP($A10,'Madras Sales'!$A$4:$P$35,AM$1+1,0) -> 3 | AN10: =VLOOKUP($A10,'Stock Transfer'!$A$3:$AE$32,16+AM$1,0) -> 2 | AO10: =AL10-AM10+AN10 -> 19
A11: F08 | B11: =VLOOKUP($A11,'Open STK'!$A$1:$E$31,4,0) -> 2 | C11: =VLOOKUP($A11,'Madras Sales'!$A$4:$P$35,C$1+1,0) -> 1 | D11: =VLOOKUP($A11,'Stock Transfer'!$A$3:$AE$32,16+C$1,0) -> 2 | E11: =B11-C11+D11 -> 3 | F11: =MAX(E11,0) -> 3 | G11: =VLOOKUP($A11,'Madras Sales'!$A$4:$P$35,G$1+1,0) -> 0 | H11: =VLOOKUP($A11,'Stock Transfer'!$A$3:$AE$32,16+G$1,0) -> 2 | I11: =F11-G11+H11 -> 5 | J11: =MAX(I11,0) -> 5 | K11: =VLOOKUP($A11,'Madras Sales'!$A$4:$P$35,K$1+1,0) -> 0 | L11: =VLOOKUP($A11,'Stock Transfer'!$A$3:$AE$32,16+K$1,0) -> 2 | M11: =J11-K11+L11 -> 7 | N11: =MAX(M11,0) -> 7 | O11: =VLOOKUP($A11,'Madras Sales'!$A$4:$P$35,O$1+1,0) -> 0 | P11: =VLOOKUP($A11,'Stock Transfer'!$A$3:$AE$32,16+O$1,0) -> 2 | Q11: =N11-O11+P11 -> 9 | R11: =MAX(Q11,0) -> 9 | S11: =VLOOKUP($A11,'Madras Sales'!$A$4:$P$35,S$1+1,0) -> 0 | T11: =VLOOKUP($A11,'Stock Transfer'!$A$3:$AE$32,16+S$1,0) -> 2 | U11: =R11-S11+T11 -> 11 | V11: =MAX(U11,0) -> 11 | W11: =VLOOKUP($A11,'Madras Sales'!$A$4:$P$35,W$1+1,0) -> 0 | X11: =VLOOKUP($A11,'Stock Transfer'!$A$3:$AE$32,16+W$1,0) -> 2 | Y11: =V11-W11+X11 -> 13 | Z11: =MAX(Y11,0) -> 13 | AA11: =VLOOKUP($A11,'Madras Sales'!$A$4:$P$35,AA$1+1,0) -> 1 | AB11: =VLOOKUP($A11,'Stock Transfer'!$A$3:$AE$32,16+AA$1,0) -> 2 | AC11: =Z11-AA11+AB11 -> 14 | AD11: =MAX(AC11,0) -> 14 | AE11: =VLOOKUP($A11,'Madras Sales'!$A$4:$P$35,AE$1+1,0) -> 0 | AF11: =VLOOKUP($A11,'Stock Transfer'!$A$3:$AE$32,16+AE$1,0) -> 2 | AG11: =AD11-AE11+AF11 -> 16 | AH11: =MAX(AG11,0) -> 16 | AI11: =VLOOKUP($A11,'Madras Sales'!$A$4:$P$35,AI$1+1,0) -> 2 | AJ11: =VLOOKUP($A11,'Stock Transfer'!$A$3:$AE$32,16+AI$1,0) -> 2 | AK11: =AH11-AI11+AJ11 -> 16 | AL11: =MAX(AK11,0) -> 16 | AM11: =VLOOKUP($A11,'Madras Sales'!$A$4:$P$35,AM$1+1,0) -> 0 | AN11: =VLOOKUP($A11,'Stock Transfer'!$A$3:$AE$32,16+AM$1,0) -> 2 | AO11: =AL11-AM11+AN11 -> 18
A12: F09 | B12: =VLOOKUP($A12,'Open STK'!$A$1:$E$31,4,0) -> 2 | C12: =VLOOKUP($A12,'Madras Sales'!$A$4:$P$35,C$1+1,0) -> 0 | D12: =VLOOKUP($A12,'Stock Transfer'!$A$3:$AE$32,16+C$1,0) -> 2 | E12: =B12-C12+D12 -> 4 | F12: =MAX(E12,0) -> 4 | G12: =VLOOKUP($A12,'Madras Sales'!$A$4:$P$35,G$1+1,0) -> 1 | H12: =VLOOKUP($A12,'Stock Transfer'!$A$3:$AE$32,16+G$1,0) -> 2 | I12: =F12-G12+H12 -> 5 | J12: =MAX(I12,0) -> 5 | K12: =VLOOKUP($A12,'Madras Sales'!$A$4:$P$35,K$1+1,0) -> 0 | L12: =VLOOKUP($A12,'Stock Transfer'!$A$3:$AE$32,16+K$1,0) -> 2 | M12: =J12-K12+L12 -> 7 | N12: =MAX(M12,0) -> 7 | O12: =VLOOKUP($A12,'Madras Sales'!$A$4:$P$35,O$1+1,0) -> 1 | P12: =VLOOKUP($A12,'Stock Transfer'!$A$3:$AE$32,16+O$1,0) -> 2 | Q12: =N12-O12+P12 -> 8 | R12: =MAX(Q12,0) -> 8 | S12: =VLOOKUP($A12,'Madras Sales'!$A$4:$P$35,S$1+1,0) -> 0 | T12: =VLOOKUP($A12,'Stock Transfer'!$A$3:$AE$32,16+S$1,0) -> 2 | U12: =R12-S12+T12 -> 10 | V12: =MAX(U12,0) -> 10 | W12: =VLOOKUP($A12,'Madras Sales'!$A$4:$P$35,W$1+1,0) -> 0 | X12: =VLOOKUP($A12,'Stock Transfer'!$A$3:$AE$32,16+W$1,0) -> 2 | Y12: =V12-W12+X12 -> 12 | Z12: =MAX(Y12,0) -> 12 | AA12: =VLOOKUP($A12,'Madras Sales'!$A$4:$P$35,AA$1+1,0) -> 0 | AB12: =VLOOKUP($A12,'Stock Transfer'!$A$3:$AE$32,16+AA$1,0) -> 2 | AC12: =Z12-AA12+AB12 -> 14 | AD12: =MAX(AC12,0) -> 14 | AE12: =VLOOKUP($A12,'Madras Sales'!$A$4:$P$35,AE$1+1,0) -> 0 | AF12: =VLOOKUP($A12,'Stock Transfer'!$A$3:$AE$32,16+AE$1,0) -> 2 | AG12: =AD12-AE12+AF12 -> 16 | AH12: =MAX(AG12,0) -> 16 | AI12: =VLOOKUP($A12,'Madras Sales'!$A$4:$P$35,AI$1+1,0) -> 1 | AJ12: =VLOOKUP($A12,'Stock Transfer'!$A$3:$AE$32,16+AI$1,0) -> 2 | AK12: =AH12-AI12+AJ12 -> 17 | AL12: =MAX(AK12,0) -> 17 | AM12: =VLOOKUP($A12,'Madras Sales'!$A$4:$P$35,AM$1+1,0) -> 0 | AN12: =VLOOKUP($A12,'Stock Transfer'!$A$3:$AE$32,16+AM$1,0) -> 2 | AO12: =AL12-AM12+AN12 -> 19
A13: F10 | B13: =VLOOKUP($A13,'Open STK'!$A$1:$E$31,4,0) -> 2 | C13: =VLOOKUP($A13,'Madras Sales'!$A$4:$P$35,C$1+1,0) -> 0 | D13: =VLOOKUP($A13,'Stock Transfer'!$A$3:$AE$32,16+C$1,0) -> 2 | E13: =B13-C13+D13 -> 4 | F13: =MAX(E13,0) -> 4 | G13: =VLOOKUP($A13,'Madras Sales'!$A$4:$P$35,G$1+1,0) -> 0 | H13: =VLOOKUP($A13,'Stock Transfer'!$A$3:$AE$32,16+G$1,0) -> 2 | I13: =F13-G13+H13 -> 6 | J13: =MAX(I13,0) -> 6 | K13: =VLOOKUP($A13,'Madras Sales'!$A$4:$P$35,K$1+1,0) -> 0 | L13: =VLOOKUP($A13,'Stock Transfer'!$A$3:$AE$32,16+K$1,0) -> 2 | M13: =J13-K13+L13 -> 8 | N13: =MAX(M13,0) -> 8 | O13: =VLOOKUP($A13,'Madras Sales'!$A$4:$P$35,O$1+1,0) -> 0 | P13: =VLOOKUP($A13,'Stock Transfer'!$A$3:$AE$32,16+O$1,0) -> 2 | Q13: =N13-O13+P13 -> 10 | R13: =MAX(Q13,0) -> 10 | S13: =VLOOKUP($A13,'Madras Sales'!$A$4:$P$35,S$1+1,0) -> 1 | T13: =VLOOKUP($A13,'Stock Transfer'!$A$3:$AE$32,16+S$1,0) -> 2 | U13: =R13-S13+T13 -> 11 | V13: =MAX(U13,0) -> 11 | W13: =VLOOKUP($A13,'Madras Sales'!$A$4:$P$35,W$1+1,0) -> 1 | X13: =VLOOKUP($A13,'Stock Transfer'!$A$3:$AE$32,16+W$1,0) -> 2 | Y13: =V13-W13+X13 -> 12 | Z13: =MAX(Y13,0) -> 12 | AA13: =VLOOKUP($A13,'Madras Sales'!$A$4:$P$35,AA$1+1,0) -> 0 | AB13: =VLOOKUP($A13,'Stock Transfer'!$A$3:$AE$32,16+AA$1,0) -> 2 | AC13: =Z13-AA13+AB13 -> 14 | AD13: =MAX(AC13,0) -> 14 | AE13: =VLOOKUP($A13,'Madras Sales'!$A$4:$P$35,AE$1+1,0) -> 0 | AF13: =VLOOKUP($A13,'Stock Transfer'!$A$3:$AE$32,16+AE$1,0) -> 2 | AG13: =AD13-AE13+AF13 -> 16 | AH13: =MAX(AG13,0) -> 16 | AI13: =VLOOKUP($A13,'Madras Sales'!$A$4:$P$35,AI$1+1,0) -> 0 | AJ13: =VLOOKUP($A13,'Stock Transfer'!$A$3:$AE$32,16+AI$1,0) -> 2 | AK13: =AH13-AI13+AJ13 -> 18 | AL13: =MAX(AK13,0) -> 18 | AM13: =VLOOKUP($A13,'Madras Sales'!$A$4:$P$35,AM$1+1,0) -> 2 | AN13: =VLOOKUP($A13,'Stock Transfer'!$A$3:$AE$32,16+AM$1,0) -> 2 | AO13: =AL13-AM13+AN13 -> 18
A14: L01 | B14: =VLOOKUP($A14,'Open STK'!$A$1:$E$31,4,0) -> 63 | C14: =VLOOKUP($A14,'Madras Sales'!$A$4:$P$35,C$1+1,0) -> 20 | D14: =VLOOKUP($A14,'Stock Transfer'!$A$3:$AE$32,16+C$1,0) -> 22 | E14: =B14-C14+D14 -> 65 | F14: =MAX(E14,0) -> 65 | G14: =VLOOKUP($A14,'Madras Sales'!$A$4:$P$35,G$1+1,0) -> 18 | H14: =VLOOKUP($A14,'Stock Transfer'!$A$3:$AE$32,16+G$1,0) -> 13 | I14: =F14-G14+H14 -> 60 | J14: =MAX(I14,0) -> 60 | K14: =VLOOKUP($A14,'Madras Sales'!$A$4:$P$35,K$1+1,0) -> 17 | L14: =VLOOKUP($A14,'Stock Transfer'!$A$3:$AE$32,16+K$1,0) -> 13 | M14: =J14-K14+L14 -> 56 | N14: =MAX(M14,0) -> 56 | O14: =VLOOKUP($A14,'Madras Sales'!$A$4:$P$35,O$1+1,0) -> 18 | P14: =VLOOKUP($A14,'Stock Transfer'!$A$3:$AE$32,16+O$1,0) -> 21 | Q14: =N14-O14+P14 -> 59 | R14: =MAX(Q14,0) -> 59 | S14: =VLOOKUP($A14,'Madras Sales'!$A$4:$P$35,S$1+1,0) -> 18 | T14: =VLOOKUP($A14,'Stock Transfer'!$A$3:$AE$32,16+S$1,0) -> 21 | U14: =R14-S14+T14 -> 62 | V14: =MAX(U14,0) -> 62 | W14: =VLOOKUP($A14,'Madras Sales'!$A$4:$P$35,W$1+1,0) -> 20 | X14: =VLOOKUP($A14,'Stock Transfer'!$A$3:$AE$32,16+W$1,0) -> 21 | Y14: =V14-W14+X14 -> 63 | Z14: =MAX(Y14,0) -> 63 | AA14: =VLOOKUP($A14,'Madras Sales'!$A$4:$P$35,AA$1+1,0) -> 25 | AB14: =VLOOKUP($A14,'Stock Transfer'!$A$3:$AE$32,16+AA$1,0) -> 14 | AC14: =Z14-AA14+AB14 -> 52 | AD14: =MAX(AC14,0) -> 52 | AE14: =VLOOKUP($A14,'Madras Sales'!$A$4:$P$35,AE$1+1,0) -> 22 | AF14: =VLOOKUP($A14,'Stock Transfer'!$A$3:$AE$32,16+AE$1,0) -> 13 | AG14: =AD14-AE14+AF14 -> 43 | AH14: =MAX(AG14,0) -> 43 | AI14: =VLOOKUP($A14,'Madras Sales'!$A$4:$P$35,AI$1+1,0) -> 19 | AJ14: =VLOOKUP($A14,'Stock Transfer'!$A$3:$AE$32,16+AI$1,0) -> 22 | AK14: =AH14-AI14+AJ14 -> 46 | AL14: =MAX(AK14,0) -> 46 | AM14: =VLOOKUP($A14,'Madras Sales'!$A$4:$P$35,AM$1+1,0) -> 24 | AN14: =VLOOKUP($A14,'Stock Transfer'!$A$3:$AE$32,16+AM$1,0) -> 17 | AO14: =AL14-AM14+AN14 -> 39
A15: L02 | B15: =VLOOKUP($A15,'Open STK'!$A$1:$E$31,4,0) -> 49 | C15: =VLOOKUP($A15,'Madras Sales'!$A$4:$P$35,C$1+1,0) -> 8 | D15: =VLOOKUP($A15,'Stock Transfer'!$A$3:$AE$32,16+C$1,0) -> 12 | E15: =B15-C15+D15 -> 53 | F15: =MAX(E15,0) -> 53 | G15: =VLOOKUP($A15,'Madras Sales'!$A$4:$P$35,G$1+1,0) -> 10 | H15: =VLOOKUP($A15,'Stock Transfer'!$A$3:$AE$32,16+G$1,0) -> 11 | I15: =F15-G15+H15 -> 54 | J15: =MAX(I15,0) -> 54 | K15: =VLOOKUP($A15,'Madras Sales'!$A$4:$P$35,K$1+1,0) -> 11 | L15: =VLOOKUP($A15,'Stock Transfer'!$A$3:$AE$32,16+K$1,0) -> 7 | M15: =J15-K15+L15 -> 50 | N15: =MAX(M15,0) -> 50 | O15: =VLOOKUP($A15,'Madras Sales'!$A$4:$P$35,O$1+1,0) -> 9 | P15: =VLOOKUP($A15,'Stock Transfer'!$A$3:$AE$32,16+O$1,0) -> 9 | Q15: =N15-O15+P15 -> 50 | R15: =MAX(Q15,0) -> 50 | S15: =VLOOKUP($A15,'Madras Sales'!$A$4:$P$35,S$1+1,0) -> 14 | T15: =VLOOKUP($A15,'Stock Transfer'!$A$3:$AE$32,16+S$1,0) -> 11 | U15: =R15-S15+T15 -> 47 | V15: =MAX(U15,0) -> 47 | W15: =VLOOKUP($A15,'Madras Sales'!$A$4:$P$35,W$1+1,0) -> 10 | X15: =VLOOKUP($A15,'Stock Transfer'!$A$3:$AE$32,16+W$1,0) -> 10 | Y15: =V15-W15+X15 -> 47 | Z15: =MAX(Y15,0) -> 47 | AA15: =VLOOKUP($A15,'Madras Sales'!$A$4:$P$35,AA$1+1,0) -> 10 | AB15: =VLOOKUP($A15,'Stock Transfer'!$A$3:$AE$32,16+AA$1,0) -> 9 | AC15: =Z15-AA15+AB15 -> 46 | AD15: =MAX(AC15,0) -> 46 | AE15: =VLOOKUP($A15,'Madras Sales'!$A$4:$P$35,AE$1+1,0) -> 10 | AF15: =VLOOKUP($A15,'Stock Transfer'!$A$3:$AE$32,16+AE$1,0) -> 12 | AG15: =AD15-AE15+AF15 -> 48 | AH15: =MAX(AG15,0) -> 48 | AI15: =VLOOKUP($A15,'Madras Sales'!$A$4:$P$35,AI$1+1,0) -> 8 | AJ15: =VLOOKUP($A15,'Stock Transfer'!$A$3:$AE$32,16+AI$1,0) -> 6 | AK15: =AH15-AI15+AJ15 -> 46 | AL15: =MAX(AK15,0) -> 46 | AM15: =VLOOKUP($A15,'Madras Sales'!$A$4:$P$35,AM$1+1,0) -> 11 | AN15: =VLOOKUP($A15,'Stock Transfer'!$A$3:$AE$32,16+AM$1,0) -> 8 | AO15: =AL15-AM15+AN15 -> 43
... A33: M10 | B33: =VLOOKUP($A33,'Open STK'!$A$1:$E$31,4,0) -> 1 | C33: =VLOOKUP($A33,'Madras Sales'!$A$4:$P$35,C$1+1,0) -> 0 | D33: =VLOOKUP($A33,'Stock Transfer'!$A$3:$AE$32,16+C$1,0) -> 2 | E33: =B33-C33+D33 -> 3 | F33: =MAX(E33,0) -> 3 | G33: =VLOOKUP($A33,'Madras Sales'!$A$4:$P$35,G$1+1,0) -> 0 | H33: =VLOOKUP($A33,'Stock Transfer'!$A$3:$AE$32,16+G$1,0) -> 2 | I33: =F33-G33+H33 -> 5 | J33: =MAX(I33,0) -> 5 | K33: =VLOOKUP($A33,'Madras Sales'!$A$4:$P$35,K$1+1,0) -> 0 | L33: =VLOOKUP($A33,'Stock Transfer'!$A$3:$AE$32,16+K$1,0) -> 2 | M33: =J33-K33+L33 -> 7 | N33: =MAX(M33,0) -> 7 | O33: =VLOOKUP($A33,'Madras Sales'!$A$4:$P$35,O$1+1,0) -> 0 | P33: =VLOOKUP($A33,'Stock Transfer'!$A$3:$AE$32,16+O$1,0) -> 2 | Q33: =N33-O33+P33 -> 9 | R33: =MAX(Q33,0) -> 9 | S33: =VLOOKUP($A33,'Madras Sales'!$A$4:$P$35,S$1+1,0) -> 1 | T33: =VLOOKUP($A33,'Stock Transfer'!$A$3:$AE$32,16+S$1,0) -> 2 | U33: =R33-S33+T33 -> 10 | V33: =MAX(U33,0) -> 10 | W33: =VLOOKUP($A33,'Madras Sales'!$A$4:$P$35,W$1+1,0) -> 1 | X33: =VLOOKUP($A33,'Stock Transfer'!$A$3:$AE$32,16+W$1,0) -> 2 | Y33: =V33-W33+X33 -> 11 | Z33: =MAX(Y33,0) -> 11 | AA33: =VLOOKUP($A33,'Madras Sales'!$A$4:$P$35,AA$1+1,0) -> 0 | AB33: =VLOOKUP($A33,'Stock Transfer'!$A$3:$AE$32,16+AA$1,0) -> 2 | AC33: =Z33-AA33+AB33 -> 13 | AD33: =MAX(AC33,0) -> 13 | AE33: =VLOOKUP($A33,'Madras Sales'!$A$4:$P$35,AE$1+1,0) -> 0 | AF33: =VLOOKUP($A33,'Stock Transfer'!$A$3:$AE$32,16+AE$1,0) -> 2 | AG33: =AD33-AE33+AF33 -> 15 | AH33: =MAX(AG33,0) -> 15 | AI33: =VLOOKUP($A33,'Madras Sales'!$A$4:$P$35,AI$1+1,0) -> 0 | AJ33: =VLOOKUP($A33,'Stock Transfer'!$A$3:$AE$32,16+AI$1,0) -> 2 | AK33: =AH33-AI33+AJ33 -> 17 | AL33: =MAX(AK33,0) -> 17 | AM33: =VLOOKUP($A33,'Madras Sales'!$A$4:$P$35,AM$1+1,0) -> 0 | AN33: =VLOOKUP($A33,'Stock Transfer'!$A$3:$AE$32,16+AM$1,0) -> 2 | AO33: =AL33-AM33+AN33 -> 19

Sheet Madras Sales
A1: City | B1: M
A3: Sum of Sales | B3: Column Labels
A4: Row Labels | B4: 44287 | C4: 44288 | D4: 44289 | E4: 44290 | F4: 44291 | G4: 44292 | H4: 44293 | I4: 44294 | J4: 44295 | K4: 44296 | L4: 44297 | M4: 44298 | N4: 44299 | O4: 44300 | P4: 44301 | Q4: Grand Total
A5: F01 | B5: 14 | C5: 9 | D5: 13 | E5: 6 | F5: 21 | G5: 18 | H5: 2 | I5: 24 | J5: 5 | K5: 13 | L5: 9 | M5: 23 | N5: 25 | O5: 2 | P5: 26 | Q5: 210
A6: F02 | B6: 13 | C6: 5 | D6: 4 | E6: 2 | F6: 7 | G6: 3 | H6: 7 | I6: 3 | J6: 1 | K6: 3 | L6: 13 | M6: 10 | N6: 3 | O6: 10 | P6: 3 | Q6: 87
A7: F03 | B7: 8 | C7: 5 | D7: 7 | E7: 0 | F7: 0 | G7: 6 | H7: 5 | I7: 0 | J7: 4 | K7: 1 | L7: 1 | M7: 9 | N7: 11 | O7: 10 | P7: 9 | Q7: 76
A8: F04 | B8: 1 | C8: 1 | D8: 3 | E8: 2 | F8: 1 | G8: 7 | H8: 2 | I8: 7 | J8: 6 | K8: 6 | L8: 4 | M8: 0 | N8: 5 | O8: 6 | P8: 8 | Q8: 59
A9: F05 | B9: 2 | C9: 0 | D9: 0 | E9: 4 | F9: 3 | G9: 7 | H9: 4 | I9: 2 | J9: 0 | K9: 3 | L9: 3 | M9: 4 | N9: 0 | O9: 0 | P9: 0 | Q9: 32
A10: F06 | B10: 0 | C10: 3 | D10: 0 | E10: 2 | F10: 1 | G10: 1 | H10: 2 | I10: 0 | J10: 3 | K10: 1 | L10: 3 | M10: 4 | N10: 1 | O10: 0 | P10: 0 | Q10: 21
A11: F07 | B11: 4 | C11: 1 | D11: 1 | E11: 0 | F11: 1 | G11: 3 | H11: 4 | I11: 2 | J11: 1 | K11: 3 | L11: 2 | M11: 0 | N11: 1 | O11: 1 | P11: 2 | Q11: 26
A12: F08 | B12: 1 | C12: 0 | D12: 0 | E12: 0 | F12: 0 | G12: 0 | H12: 1 | I12: 0 | J12: 2 | K12: 0 | L12: 0 | M12: 1 | N12: 0 | O12: 1 | P12: 0 | Q12: 6
A13: F09 | B13: 0 | C13: 1 | D13: 0 | E13: 1 | F13: 0 | G13: 0 | H13: 0 | I13: 0 | J13: 1 | K13: 0 | L13: 0 | M13: 0 | N13: 0 | O13: 0 | P13: 0 | Q13: 3
A14: F10 | B14: 0 | C14: 0 | D14: 0 | E14: 0 | F14: 1 | G14: 1 | H14: 0 | I14: 0 | J14: 0 | K14: 2 | L14: 0 | M14: 0 | N14: 0 | O14: 0 | P14: 0 | Q14: 4
A15: L01 | B15: 20 | C15: 18 | D15: 17 | E15: 18 | F15: 18 | G15: 20 | H15: 25 | I15: 22 | J15: 19 | K15: 24 | L15: 20 | M15: 19 | N15: 24 | O15: 19 | P15: 18 | Q15: 301
A16: L02 | B16: 8 | C16: 10 | D16: 11 | E16: 9 | F16: 14 | G16: 10 | H16: 10 | I16: 10 | J16: 8 | K16: 11 | L16: 8 | M16: 8 | N16: 9 | O16: 10 | P16: 13 | Q16: 149
... A35: Grand Total | B35: 140 | C35: 120 | D35: 133 | E35: 119 | F35: 144 | G35: 150 | H35: 133 | I35: 137 | J35: 121 | K35: 140 | L35: 136 | M35: 152 | N35: 153 | O35: 133 | P35: 154 | Q35: 2065

Sheet Revenue Pareto
A3: Row Labels | B3: Sum of Revenue | D3: Row Labels | E3: Sum of revenue | F3: Cumulative Revenue | G3: %cum rev
A4: F01 | B4: 2923886 | D4: F01 | E4: 2923886 | F4: 2923886 | G4: =F4/GETPIVOTDATA("Revenue",$A$3) -> 0.38078904
A5: F02 | B5: 159159 | D5: F02 | E5: 159159 | F5: =F4+E5 -> 3083045 | G5: =F5/GETPIVOTDATA("Revenue",$A$3) -> 0.40151694
A6: F03 | B6: 763600 | D6: F03 | E6: 763600 | F6: =F5+E6 -> 3846645 | G6: =F6/GETPIVOTDATA("Revenue",$A$3) -> 0.50096354
A7: F04 | B7: 136726 | D7: F04 | E7: 136726 | F7: =F6+E7 -> 3983371 | G7: =F7/GETPIVOTDATA("Revenue",$A$3) -> 0.51876989
A8: F05 | B8: 55315 | D8: F05 | E8: 55315 | F8: =F7+E8 -> 4038686 | G8: =F8/GETPIVOTDATA("Revenue",$A$3) -> 0.52597378
A9: F06 | B9: 100912 | D9: F06 | E9: 100912 | F9: =F8+E9 -> 4139598 | G9: =F9/GETPIVOTDATA("Revenue",$A$3) -> 0.53911594
A10: F07 | B10: 104048 | D10: F07 | E10: 104048 | F10: =F9+E10 -> 4243646 | G10: =F10/GETPIVOTDATA("Revenue",$A$3) -> 0.55266652
A11: F08 | B11: 39140 | D11: F08 | E11: 39140 | F11: =F10+E11 -> 4282786 | G11: =F11/GETPIVOTDATA("Revenue",$A$3) -> 0.55776387
A12: F09 | B12: 45214 | D12: F09 | E12: 45214 | F12: =F11+E12 -> 4328000 | G12: =F12/GETPIVOTDATA("Revenue",$A$3) -> 0.56365227
A13: F10 | B13: 33099 | D13: F10 | E13: 33099 | F13: =F12+E13 -> 4361099 | G13: =F13/GETPIVOTDATA("Revenue",$A$3) -> 0.56796288
A14: L01 | B14: 1612800 | D14: L01 | E14: 1612800 | F14: =F13+E14 -> 5973899 | G14: =F14/GETPIVOTDATA("Revenue",$A$3) -> 0.7780041
A15: L02 | B15: 157665 | D15: L02 | E15: 157665 | F15: =F14+E15 -> 6131564 | G15: =F15/GETPIVOTDATA("Revenue",$A$3) -> 0.79853742
A16: L03 | B16: 116550 | D16: L03 | E16: 116550 | F16: =F15+E16 -> 6248114 | G16: =F16/GETPIVOTDATA("Revenue",$A$3) -> 0.81371618
... A33: M10 | B33: 16770 | D33: M10 | E33: 16770 | F33: =F32+E33 -> 7678493 | G33: =F33/GETPIVOTDATA("Revenue",$A$3) -> 1
A34: Grand Total | B34: 7678493
B39: Day-wise sales
B40: Day | C40: Sales
B41: Monday | C41: 208
B42: Tuesday | C42: 227
B43: Wednesday | C43: 266
B44: Thursday | C44: 346
B45: Friday | C45: 277
B46: Saturday | C46: 239
B47: Sunday | C47: 267
B48: Minimum | C48: =MIN(C41:C47) -> 208

Sheet Volume Analysis
A3: Row Labels | B3: Sum of Sales | D3: Row Labels | E3: Sum of sales | F3: Cumulative Sales | G3: %cumulative sales
A4: F01 | B4: 914 | D4: F01 | E4: 914 | F4: 914 | G4: =F4/GETPIVOTDATA("Sales",$A$3) -> 0.1228825
A5: F02 | B5: 429 | D5: F02 | E5: 429 | F5: =F4+E5 -> 1343 | G5: =F5/GETPIVOTDATA("Sales",$A$3) -> 0.18055929
A6: F03 | B6: 332 | D6: F03 | E6: 332 | F6: =F5+E6 -> 1675 | G6: =F6/GETPIVOTDATA("Sales",$A$3) -> 0.22519494
A7: F04 | B7: 274 | D7: F04 | E7: 274 | F7: =F6+E7 -> 1949 | G7: =F7/GETPIVOTDATA("Sales",$A$3) -> 0.2620328
A8: F05 | B8: 185 | D8: F05 | E8: 185 | F8: =F7+E8 -> 2134 | G8: =F8/GETPIVOTDATA("Sales",$A$3) -> 0.28690508
A9: F06 | B9: 112 | D9: F06 | E9: 112 | F9: =F8+E9 -> 2246 | G9: =F9/GETPIVOTDATA("Sales",$A$3) -> 0.30196289
A10: F07 | B10: 112 | D10: F07 | E10: 112 | F10: =F9+E10 -> 2358 | G10: =F10/GETPIVOTDATA("Sales",$A$3) -> 0.3170207
A11: F08 | B11: 38 | D11: F08 | E11: 38 | F11: =F10+E11 -> 2396 | G11: =F11/GETPIVOTDATA("Sales",$A$3) -> 0.3221296
A12: F09 | B12: 37 | D12: F09 | E12: 37 | F12: =F11+E12 -> 2433 | G12: =F12/GETPIVOTDATA("Sales",$A$3) -> 0.32710406
A13: F10 | B13: 51 | D13: F10 | E13: 51 | F13: =F12+E13 -> 2484 | G13: =F13/GETPIVOTDATA("Sales",$A$3) -> 0.33396074
A14: L01 | B14: 896 | D14: L01 | E14: 896 | F14: =F13+E14 -> 3380 | G14: =F14/GETPIVOTDATA("Sales",$A$3) -> 0.45442323
A15: L02 | B15: 457 | D15: L02 | E15: 457 | F15: =F14+E15 -> 3837 | G15: =F15/GETPIVOTDATA("Sales",$A$3) -> 0.51586448
A16: L03 | B16: 333 | D16: L03 | E16: 333 | F16: =F15+E16 -> 4170 | G16: =F16/GETPIVOTDATA("Sales",$A$3) -> 0.56063458
... A33: M10 | B33: 30 | D33: M10 | E33: 30 | F33: =F32+E33 -> 7438 | G33: =F33/GETPIVOTDATA("Sales",$A$3) -> 1
A34: Grand Total | B34: 7438

Sheet Rev_Vol
A1: City | B1: M
E2: Cochin | I2: Hyderabad | M2: Madras
A3: Row Labels | B3: Sum of Sales | C3: Sum of Revenue | E3: SKUs | F3: Volume | G3: Revenue | I3: SKUs | J3: Volume | K3: Revenue | M3: SKUs | N3: Volume | O3: Revenue
A4: F01 | B4: 210 | C4: 671790 | E4: L10 | F4: 10 | G4: 14770 | I4: L10 | J4: 6 | K4: 8862 | M4: L09 | N4: 1 | O4: 1800
A5: F02 | B5: 87 | C5: 32277 | E5: M08 | F5: 12 | G5: 876 | I5: M10 | J5: 8 | K5: 4472 | M5: F09 | N5: 3 | O5: 3666
A6: F03 | B6: 76 | C6: 174800 | E6: M10 | F6: 18 | G6: 10062 | I6: L09 | J6: 9 | K6: 16200 | M6: F10 | N6: 4 | O6: 2596
A7: F04 | B7: 59 | C7: 29441 | E7: F08 | F7: 20 | G7: 20600 | I7: M08 | J7: 11 | K7: 803 | M7: L10 | N7: 4 | O7: 5908
A8: F05 | B8: 32 | C8: 9568 | E8: L09 | F8: 20 | G8: 36000 | I8: F08 | J8: 12 | K8: 12360 | M8: M10 | N8: 4 | O8: 2236
A9: F06 | B9: 21 | C9: 18921 | E9: M09 | F9: 20 | G9: 4500 | I9: L08 | J9: 12 | K9: 18000 | M9: L08 | N9: 5 | O9: 7500
A10: F07 | B10: 26 | C10: 24154 | E10: F09 | F10: 21 | G10: 25662 | I10: F09 | J10: 13 | K10: 15886 | M10: M08 | N10: 5 | O10: 365
A11: F08 | B11: 6 | C11: 6180 | E11: L08 | F11: 22 | G11: 33000 | I11: M09 | J11: 14 | K11: 3150 | M11: F08 | N11: 6 | O11: 6180
A12: F09 | B12: 3 | C12: 3666 | E12: M06 | F12: 27 | G12: 3294 | I12: F10 | J12: 19 | K12: 12331 | M12: M09 | N12: 6 | O12: 1350
A13: F10 | B13: 4 | C13: 2596 | E13: F10 | F13: 28 | G13: 18172 | I13: L07 | J13: 45 | K13: 16830 | M13: L07 | N13: 8 | O13: 2992
A14: L01 | B14: 301 | C14: 541800 | E14: M07 | F14: 28 | G14: 2688 | I14: F06 | J14: 46 | K14: 41446 | M14: L06 | N14: 18 | O14: 21348
A15: L02 | B15: 149 | C15: 51405 | E15: F07 | F15: 37 | G15: 34373 | I15: L06 | J15: 48 | K15: 56928 | M15: F06 | N15: 21 | O15: 18921
... A33: M10 | B33: 4 | C33: 2236 | E33: F01 | F33: 261 | G33: 834939 | I33: M01 | J33: 464 | K33: 97440 | M33: M01 | N33: 317 | O33: 66570
A34: Grand Total | B34: 2065 | C34: 1988557

Sheet Daily Revenue
A3: Row Labels | B3: Sum of Revenue | D3: Dates | E3: Total Revenue | F3: Cumulative Revenue | G3: % cumRev | H3: %growth
A4: 44287 | B4: 482300 | D4: 44287 | E4: 482300 | F4: 482300 | G4: =F4/GETPIVOTDATA("Revenue",$A$3) -> 0.062811804 | I4: 44287
A5: 44288 | B5: 516662 | D5: 44288 | E5: 516662 | F5: =F4+E5 -> 998962 | G5: =F5/GETPIVOTDATA("Revenue",$A$3) -> 0.13009871 | H5: =G5-G4 -> 0.067286901 | I5: 44288
A6: 44289 | B6: 519461 | D6: 44289 | E6: 519461 | F6: =F5+E6 -> 1518423 | G6: =F6/GETPIVOTDATA("Revenue",$A$3) -> 0.19775013 | H6: =G6-G5 -> 0.067651426 | I6: 44289
A7: 44290 | B7: 526452 | D7: 44290 | E7: 526452 | F7: =F6+E7 -> 2044875 | G7: =F7/GETPIVOTDATA("Revenue",$A$3) -> 0.26631202 | H7: =G7-G6 -> 0.068561891 | I7: 44290
A8: 44291 | B8: 505618 | D8: 44291 | E8: 505618 | F8: =F7+E8 -> 2550493 | G8: =F8/GETPIVOTDATA("Revenue",$A$3) -> 0.33216062 | H8: =G8-G7 -> 0.065848598 | I8: 44291 | K8: Max growth | L8: =MAX(H5:H18) -> 0.069963338
A9: 44292 | B9: 505672 | D9: 44292 | E9: 505672 | F9: =F8+E9 -> 3056165 | G9: =F9/GETPIVOTDATA("Revenue",$A$3) -> 0.39801625 | H9: =G9-G8 -> 0.065855631 | I9: 44292 | K9: Date for max | L9: =VLOOKUP(L8,H5:I18,2,0) -> 44299
A10: 44293 | B10: 517023 | D10: 44293 | E10: 517023 | F10: =F9+E10 -> 3573188 | G10: =F10/GETPIVOTDATA("Revenue",$A$3) -> 0.46535017 | H10: =G10-G9 -> 0.067333916 | I10: 44293
A11: 44294 | B11: 501575 | D11: 44294 | E11: 501575 | F11: =F10+E11 -> 4074763 | G11: =F11/GETPIVOTDATA("Revenue",$A$3) -> 0.53067223 | H11: =G11-G10 -> 0.065322063 | I11: 44294
A12: 44295 | B12: 524258 | D12: 44295 | E12: 524258 | F12: =F11+E12 -> 4599021 | G12: =F12/GETPIVOTDATA("Revenue",$A$3) -> 0.59894839 | H12: =G12-G11 -> 0.068276158 | I12: 44295
A13: 44296 | B13: 524265 | D13: 44296 | E13: 524265 | F13: =F12+E13 -> 5123286 | G13: =F13/GETPIVOTDATA("Revenue",$A$3) -> 0.66722546 | H13: =G13-G12 -> 0.068277069 | I13: 44296
A14: 44297 | B14: 505666 | D14: 44297 | E14: 505666 | F14: =F13+E14 -> 5628952 | G14: =F14/GETPIVOTDATA("Revenue",$A$3) -> 0.73308031 | H14: =G14-G13 -> 0.065854849 | I14: 44297
A15: 44298 | B15: 496066 | D15: 44298 | E15: 496066 | F15: =F14+E15 -> 6125018 | G15: =F15/GETPIVOTDATA("Revenue",$A$3) -> 0.79768491 | H15: =G15-G14 -> 0.064604604 | I15: 44298
A16: 44299 | B16: 537213 | D16: 44299 | E16: 537213 | F16: =F15+E16 -> 6662231 | G16: =F16/GETPIVOTDATA("Revenue",$A$3) -> 0.86764825 | H16: =G16-G15 -> 0.069963338 | I16: 44299
A17: 44300 | B17: 515809 | D17: 44300 | E17: 515809 | F17: =F16+E17 -> 7178040 | G17: =F17/GETPIVOTDATA("Revenue",$A$3) -> 0.93482406 | H17: =G17-G16 -> 0.067175812 | I17: 44300
A18: 44301 | B18: 500453 | D18: 44301 | E18: 500453 | F18: =F17+E18 -> 7678493 | G18: =F18/GETPIVOTDATA("Revenue",$A$3) -> 1 | H18: =G18-G17 -> 0.06517594 | I18: 44301
A19: Grand Total | B19: 7678493
G21: Date | H21: % growth
G22: 44287
G23: 44288 | H23: 0.067286901
G24: 44289 | H24: 0.067651426
G25: 44290 | H25: 0.068561891
G26: 44291 | H26: 0.065848598
G27: 44292 | H27: 0.065855631
G28: 44293 | H28: 0.067333916
G29: 44294 | H29: 0.065322063
G30: 44295 | H30: 0.068276158
G31: 44296 | H31: 0.068277069
G32: 44297 | H32: 0.065854849
G33: 44298 | H33: 0.064604604
G34: 44299 | H34: 0.069963338
... G36: 44301 | H36: 0.06517594

Sheet Cochin Ledger
C1: 1 | G1: =C1+1 -> 2 | K1: =G1+1 -> 3 | O1: =K1+1 -> 4 | S1: =O1+1 -> 5 | W1: =S1+1 -> 6 | AA1: =W1+1 -> 7 | AE1: =AA1+1 -> 8 | AI1: =AE1+1 -> 9 | AM1: =AI1+1 -> 10 | AQ1: =AM1+1 -> 11 | AU1: =AQ1+1 -> 12 | AY1: =AU1+1 -> 13 | BC1: =AY1+1 -> 14 | BG1: =BC1+1 -> 15
B2: =DATE(2021,4,C1) -> 44287 | F2: =DATE(2021,4,G1) -> 44288 | J2: =DATE(2021,4,K1) -> 44289 | N2: =DATE(2021,4,O1) -> 44290 | R2: =DATE(2021,4,S1) -> 44291 | V2: =DATE(2021,4,W1) -> 44292 | Z2: =DATE(2021,4,AA1) -> 44293 | AD2: =DATE(2021,4,AE1) -> 44294 | AH2: =DATE(2021,4,AI1) -> 44295 | AL2: =DATE(2021,4,AM1) -> 44296 | AP2: =DATE(2021,4,AQ1) -> 44297 | AT2: =DATE(2021,4,AU1) -> 44298 | AX2: =DATE(2021,4,AY1) -> 44299 | BB2: =DATE(2021,4,BC1) -> 44300 | BF2: =DATE(2021,4,BG1) -> 44301
A3: SKU | B3: Open Stock | C3: Sales | D3: Incoming | E3: Closing Stock | F3: Open Stock | G3: Sales | H3: Incoming | I3: Closing Stock | J3: Open Stock | K3: Sales | L3: Incoming | M3: Closing Stock | N3: Open Stock | O3: Sales | P3: Incoming | Q3: Closing Stock | R3: Open Stock | S3: Sales | T3: Incoming | U3: Closing Stock | V3: Open Stock | W3: Sales | X3: Incoming | Y3: Closing Stock | Z3: Open Stock | AA3: Sales | AB3: Incoming | AC3: Closing Stock | AD3: Open Stock | AE3: Sales | AF3: Incoming | AG3: Closing Stock | AH3: Open Stock | AI3: Sales | AJ3: Incoming | AK3: Closing Stock | AL3: Open Stock | AM3: Sales | AN3: Incoming | AO3: Closing Stock | AP3: Open Stock | AQ3: Sales | AR3: Incoming | AS3: Closing Stock | AT3: Open Stock | AU3: Sales | AV3: Incoming | AW3: Closing Stock | AX3: Open Stock | AY3: Sales | AZ3: Incoming | BA3: Closing Stock | BB3: Open Stock | BC3: Sales | BD3: Incoming | BE3: Closing Stock | BF3: Open Stock | BG3: Sales | BH3: Incoming | BI3: Closing Stock
A4: F01 | B4: =VLOOKUP($A4,'Open STK'!$A$1:$E$31,3,0) -> 75 | C4: =VLOOKUP($A4,C_Sales!$A$4:$P$35,C$1+1,0) -> 12 | D4: =VLOOKUP($A4,'Stock Transfer'!$A$3:$AE$32,1+C$1,0) -> 11 | E4: =B4-C4+D4 -> 74 | F4: =MAX(E4,0) -> 74 | G4: =VLOOKUP($A4,C_Sales!$A$4:$P$35,G$1+1,0) -> 28 | H4: =VLOOKUP($A4,'Stock Transfer'!$A$3:$AE$32,1+G$1,0) -> 22 | I4: =F4-G4+H4 -> 68 | J4: =MAX(I4,0) -> 68 | K4: =VLOOKUP($A4,C_Sales!$A$4:$P$35,K$1+1,0) -> 23 | L4: =VLOOKUP($A4,'Stock Transfer'!$A$3:$AE$32,1+K$1,0) -> 16 | M4: =J4-K4+L4 -> 61 | N4: =MAX(M4,0) -> 61 | O4: =VLOOKUP($A4,C_Sales!$A$4:$P$35,O$1+1,0) -> 24 | P4: =VLOOKUP($A4,'Stock Transfer'!$A$3:$AE$32,1+O$1,0) -> 18 | Q4: =N4-O4+P4 -> 55 | R4: =MAX(Q4,0) -> 55 | S4: =VLOOKUP($A4,C_Sales!$A$4:$P$35,S$1+1,0) -> 14 | T4: =VLOOKUP($A4,'Stock Transfer'!$A$3:$AE$32,1+S$1,0) -> 14 | U4: =R4-S4+T4 -> 55 | V4: =MAX(U4,0) -> 55 | W4: =VLOOKUP($A4,C_Sales!$A$4:$P$35,W$1+1,0) -> 8 | X4: =VLOOKUP($A4,'Stock Transfer'!$A$3:$AE$32,1+W$1,0) -> 20 | Y4: =V4-W4+X4 -> 67 | Z4: =MAX(Y4,0) -> 67 | AA4: =VLOOKUP($A4,C_Sales!$A$4:$P$35,AA$1+1,0) -> 21 | AB4: =VLOOKUP($A4,'Stock Transfer'!$A$3:$AE$32,1+AA$1,0) -> 16 | AC4: =Z4-AA4+AB4 -> 62 | AD4: =MAX(AC4,0) -> 62 | AE4: =VLOOKUP($A4,C_Sales!$A$4:$P$35,AE$1+1,0) -> 1 | AF4: =VLOOKUP($A4,'Stock Transfer'!$A$3:$AE$32,1+AE$1,0) -> 13 | AG4: =AD4-AE4+AF4 -> 74 | AH4: =MAX(AG4,0) -> 74 | AI4: =VLOOKUP($A4,C_Sales!$A$4:$P$35,AI$1+1,0) -> 30 | AJ4: =VLOOKUP($A4,'Stock Transfer'!$A$3:$AE$32,1+AI$1,0) -> 17 | AK4: =AH4-AI4+AJ4 -> 61 | AL4: =MAX(AK4,0) -> 61 | AM4: =VLOOKUP($A4,C_Sales!$A$4:$P$35,AM$1+1,0) -> 23 | AN4: =VLOOKUP($A4,'Stock Transfer'!$A$3:$AE$32,1+AM$1,0) -> 16 | AO4: =AL4-AM4+AN4 -> 54 | AP4: =MAX(AO4,0) -> 54 | AQ4: =VLOOKUP($A4,C_Sales!$A$4:$P$35,AQ$1+1,0) -> 21 | AR4: =VLOOKUP($A4,'Stock Transfer'!$A$3:$AE$32,1+AQ$1,0) -> 14 | AS4: =AP4-AQ4+AR4 -> 47 | AT4: =MAX(AS4,0) -> 47 | AU4: =VLOOKUP($A4,C_Sales!$A$4:$P$35,AU$1+1,0) -> 14 | AV4: =VLOOKUP($A4,'Stock Transfer'!$A$3:$AE$32,1+AU$1,0) -> 9 | AW4: =AT4-AU4+AV4 -> 42 | AX4: =MAX(AW4,0) -> 42 | AY4: =VLOOKUP($A4,C_Sales!$A$4:$P$35,AY$1+1,0) -> 13 | AZ4: =VLOOKUP($A4,'Stock Transfer'!$A$3:$AE$32,1+AY$1,0) -> 14 | BA4: =AX4-AY4+AZ4 -> 43 | BB4: =MAX(BA4,0) -> 43 | BC4: =VLOOKUP($A4,C_Sales!$A$4:$P$35,BC$1+1,0) -> 28 | BD4: =VLOOKUP($A4,'Stock Transfer'!$A$3:$AE$32,1+BC$1,0) -> 12 | BE4: =BB4-BC4+BD4 -> 27 | BF4: =MAX(BE4,0) -> 27 | BG4: =VLOOKUP($A4,C_Sales!$A$4:$P$35,BG$1+1,0) -> 1 | BH4: =VLOOKUP($A4,'Stock Transfer'!$A$3:$AE$32,1+BG$1,0) -> 20 | BI4: =BF4-BG4+BH4 -> 46 | BK4: Lowest Closing Inventory | BN4: =MIN(BI4:BI33) -> 15
A5: F02 | B5: =VLOOKUP($A5,'Open STK'!$A$1:$E$31,4,0) -> 24 | C5: =VLOOKUP($A5,C_Sales!$A$4:$P$35,C$1+1,0) -> 3 | D5: =VLOOKUP($A5,'Stock Transfer'!$A$3:$AE$32,1+C$1,0) -> 6 | E5: =B5-C5+D5 -> 27 | F5: =MAX(E5,0) -> 27 | G5: =VLOOKUP($A5,C_Sales!$A$4:$P$35,G$1+1,0) -> 7 | H5: =VLOOKUP($A5,'Stock Transfer'!$A$3:$AE$32,1+G$1,0) -> 8 | I5: =F5-G5+H5 -> 28 | J5: =MAX(I5,0) -> 28 | K5: =VLOOKUP($A5,C_Sales!$A$4:$P$35,K$1+1,0) -> 13 | L5: =VLOOKUP($A5,'Stock Transfer'!$A$3:$AE$32,1+K$1,0) -> 7 | M5: =J5-K5+L5 -> 22 | N5: =MAX(M5,0) -> 22 | O5: =VLOOKUP($A5,C_Sales!$A$4:$P$35,O$1+1,0) -> 14 | P5: =VLOOKUP($A5,'Stock Transfer'!$A$3:$AE$32,1+O$1,0) -> 10 | Q5: =N5-O5+P5 -> 18 | R5: =MAX(Q5,0) -> 18 | S5: =VLOOKUP($A5,C_Sales!$A$4:$P$35,S$1+1,0) -> 6 | T5: =VLOOKUP($A5,'Stock Transfer'!$A$3:$AE$32,1+S$1,0) -> 8 | U5: =R5-S5+T5 -> 20 | V5: =MAX(U5,0) -> 20 | W5: =VLOOKUP($A5,C_Sales!$A$4:$P$35,W$1+1,0) -> 11 | X5: =VLOOKUP($A5,'Stock Transfer'!$A$3:$AE$32,1+W$1,0) -> 9 | Y5: =V5-W5+X5 -> 18 | Z5: =MAX(Y5,0) -> 18 | AA5: =VLOOKUP($A5,C_Sales!$A$4:$P$35,AA$1+1,0) -> 9 | AB5: =VLOOKUP($A5,'Stock Transfer'!$A$3:$AE$32,1+AA$1,0) -> 8 | AC5: =Z5-AA5+AB5 -> 17 | AD5: =MAX(AC5,0) -> 17 | AE5: =VLOOKUP($A5,C_Sales!$A$4:$P$35,AE$1+1,0) -> 10 | AF5: =VLOOKUP($A5,'Stock Transfer'!$A$3:$AE$32,1+AE$1,0) -> 7 | AG5: =AD5-AE5+AF5 -> 14 | AH5: =MAX(AG5,0) -> 14 | AI5: =VLOOKUP($A5,C_Sales!$A$4:$P$35,AI$1+1,0) -> 11 | AJ5: =VLOOKUP($A5,'Stock Transfer'!$A$3:$AE$32,1+AI$1,0) -> 8 | AK5: =AH5-AI5+AJ5 -> 11 | AL5: =MAX(AK5,0) -> 11 | AM5: =VLOOKUP($A5,C_Sales!$A$4:$P$35,AM$1+1,0) -> 10 | AN5: =VLOOKUP($A5,'Stock Transfer'!$A$3:$AE$32,1+AM$1,0) -> 10 | AO5: =AL5-AM5+AN5 -> 11 | AP5: =MAX(AO5,0) -> 11 | AQ5: =VLOOKUP($A5,C_Sales!$A$4:$P$35,AQ$1+1,0) -> 1 | AR5: =VLOOKUP($A5,'Stock Transfer'!$A$3:$AE$32,1+AQ$1,0) -> 6 | AS5: =AP5-AQ5+AR5 -> 16 | AT5: =MAX(AS5,0) -> 16 | AU5: =VLOOKUP($A5,C_Sales!$A$4:$P$35,AU$1+1,0) -> 6 | AV5: =VLOOKUP($A5,'Stock Transfer'!$A$3:$AE$32,1+AU$1,0) -> 10 | AW5: =AT5-AU5+AV5 -> 20 | AX5: =MAX(AW5,0) -> 20 | AY5: =VLOOKUP($A5,C_Sales!$A$4:$P$35,AY$1+1,0) -> 13 | AZ5: =VLOOKUP($A5,'Stock Transfer'!$A$3:$AE$32,1+AY$1,0) -> 7 | BA5: =AX5-AY5+AZ5 -> 14 | BB5: =MAX(BA5,0) -> 14 | BC5: =VLOOKUP($A5,C_Sales!$A$4:$P$35,BC$1+1,0) -> 1 | BD5: =VLOOKUP($A5,'Stock Transfer'!$A$3:$AE$32,1+BC$1,0) -> 11 | BE5: =BB5-BC5+BD5 -> 24 | BF5: =MAX(BE5,0) -> 24 | BG5: =VLOOKUP($A5,C_Sales!$A$4:$P$35,BG$1+1,0) -> 16 | BH5: =VLOOKUP($A5,'Stock Transfer'!$A$3:$AE$32,1+BG$1,0) -> 7 | BI5: =BF5-BG5+BH5 -> 15 | BK5: SKU for lowest | BN5: =VLOOKUP(BN4,A3:BI33,61,0) -> #N/A
A6: F03 | B6: =VLOOKUP($A6,'Open STK'!$A$1:$E$31,4,0) -> 12 | C6: =VLOOKUP($A6,C_Sales!$A$4:$P$35,C$1+1,0) -> 3 | D6: =VLOOKUP($A6,'Stock Transfer'!$A$3:$AE$32,1+C$1,0) -> 9 | E6: =B6-C6+D6 -> 18 | F6: =MAX(E6,0) -> 18 | G6: =VLOOKUP($A6,C_Sales!$A$4:$P$35,G$1+1,0) -> 5 | H6: =VLOOKUP($A6,'Stock Transfer'!$A$3:$AE$32,1+G$1,0) -> 7 | I6: =F6-G6+H6 -> 20 | J6: =MAX(I6,0) -> 20 | K6: =VLOOKUP($A6,C_Sales!$A$4:$P$35,K$1+1,0) -> 3 | L6: =VLOOKUP($A6,'Stock Transfer'!$A$3:$AE$32,1+K$1,0) -> 8 | M6: =J6-K6+L6 -> 25 | N6: =MAX(M6,0) -> 25 | O6: =VLOOKUP($A6,C_Sales!$A$4:$P$35,O$1+1,0) -> 10 | P6: =VLOOKUP($A6,'Stock Transfer'!$A$3:$AE$32,1+O$1,0) -> 6 | Q6: =N6-O6+P6 -> 21 | R6: =MAX(Q6,0) -> 21 | S6: =VLOOKUP($A6,C_Sales!$A$4:$P$35,S$1+1,0) -> 9 | T6: =VLOOKUP($A6,'Stock Transfer'!$A$3:$AE$32,1+S$1,0) -> 6 | U6: =R6-S6+T6 -> 18 | V6: =MAX(U6,0) -> 18 | W6: =VLOOKUP($A6,C_Sales!$A$4:$P$35,W$1+1,0) -> 7 | X6: =VLOOKUP($A6,'Stock Transfer'!$A$3:$AE$32,1+W$1,0) -> 8 | Y6: =V6-W6+X6 -> 19 | Z6: =MAX(Y6,0) -> 19 | AA6: =VLOOKUP($A6,C_Sales!$A$4:$P$35,AA$1+1,0) -> 10 | AB6: =VLOOKUP($A6,'Stock Transfer'!$A$3:$AE$32,1+AA$1,0) -> 5 | AC6: =Z6-AA6+AB6 -> 14 | AD6: =MAX(AC6,0) -> 14 | AE6: =VLOOKUP($A6,C_Sales!$A$4:$P$35,AE$1+1,0) -> 10 | AF6: =VLOOKUP($A6,'Stock Transfer'!$A$3:$AE$32,1+AE$1,0) -> 6 | AG6: =AD6-AE6+AF6 -> 10 | AH6: =MAX(AG6,0) -> 10 | AI6: =VLOOKUP($A6,C_Sales!$A$4:$P$35,AI$1+1,0) -> 6 | AJ6: =VLOOKUP($A6,'Stock Transfer'!$A$3:$AE$32,1+AI$1,0) -> 6 | AK6: =AH6-AI6+AJ6 -> 10 | AL6: =MAX(AK6,0) -> 10 | AM6: =VLOOKUP($A6,C_Sales!$A$4:$P$35,AM$1+1,0) -> 11 | AN6: =VLOOKUP($A6,'Stock Transfer'!$A$3:$AE$32,1+AM$1,0) -> 7 | AO6: =AL6-AM6+AN6 -> 6 | AP6: =MAX(AO6,0) -> 6 | AQ6: =VLOOKUP($A6,C_Sales!$A$4:$P$35,AQ$1+1,0) -> 10 | AR6: =VLOOKUP($A6,'Stock Transfer'!$A$3:$AE$32,1+AQ$1,0) -> 5 | AS6: =AP6-AQ6+AR6 -> 1 | AT6: =MAX(AS6,0) -> 1 | AU6: =VLOOKUP($A6,C_Sales!$A$4:$P$35,AU$1+1,0) -> 2 | AV6: =VLOOKUP($A6,'Stock Transfer'!$A$3:$AE$32,1+AU$1,0) -> 8 | AW6: =AT6-AU6+AV6 -> 7 | AX6: =MAX(AW6,0) -> 7 | AY6: =VLOOKUP($A6,C_Sales!$A$4:$P$35,AY$1+1,0) -> 2 | AZ6: =VLOOKUP($A6,'Stock Transfer'!$A$3:$AE$32,1+AY$1,0) -> 7 | BA6: =AX6-AY6+AZ6 -> 12 | BB6: =MAX(BA6,0) -> 12 | BC6: =VLOOKUP($A6,C_Sales!$A$4:$P$35,BC$1+1,0) -> 4 | BD6: =VLOOKUP($A6,'Stock Transfer'!$A$3:$AE$32,1+BC$1,0) -> 7 | BE6: =BB6-BC6+BD6 -> 15 | BF6: =MAX(BE6,0) -> 15 | BG6: =VLOOKUP($A6,C_Sales!$A$4:$P$35,BG$1+1,0) -> 3 | BH6: =VLOOKUP($A6,'Stock Transfer'!$A$3:$AE$32,1+BG$1,0) -> 5 | BI6: =BF6-BG6+BH6 -> 17
A7: F04 | B7: =VLOOKUP($A7,'Open STK'!$A$1:$E$31,4,0) -> 14 | C7: =VLOOKUP($A7,C_Sales!$A$4:$P$35,C$1+1,0) -> 8 | D7: =VLOOKUP($A7,'Stock Transfer'!$A$3:$AE$32,1+C$1,0) -> 7 | E7: =B7-C7+D7 -> 13 | F7: =MAX(E7,0) -> 13 | G7: =VLOOKUP($A7,C_Sales!$A$4:$P$35,G$1+1,0) -> 8 | H7: =VLOOKUP($A7,'Stock Transfer'!$A$3:$AE$32,1+G$1,0) -> 7 | I7: =F7-G7+H7 -> 12 | J7: =MAX(I7,0) -> 12 | K7: =VLOOKUP($A7,C_Sales!$A$4:$P$35,K$1+1,0) -> 5 | L7: =VLOOKUP($A7,'Stock Transfer'!$A$3:$AE$32,1+K$1,0) -> 7 | M7: =J7-K7+L7 -> 14 | N7: =MAX(M7,0) -> 14 | O7: =VLOOKUP($A7,C_Sales!$A$4:$P$35,O$1+1,0) -> 6 | P7: =VLOOKUP($A7,'Stock Transfer'!$A$3:$AE$32,1+O$1,0) -> 5 | Q7: =N7-O7+P7 -> 13 | R7: =MAX(Q7,0) -> 13 | S7: =VLOOKUP($A7,C_Sales!$A$4:$P$35,S$1+1,0) -> 7 | T7: =VLOOKUP($A7,'Stock Transfer'!$A$3:$AE$32,1+S$1,0) -> 7 | U7: =R7-S7+T7 -> 13 | V7: =MAX(U7,0) -> 13 | W7: =VLOOKUP($A7,C_Sales!$A$4:$P$35,W$1+1,0) -> 1 | X7: =VLOOKUP($A7,'Stock Transfer'!$A$3:$AE$32,1+W$1,0) -> 5 | Y7: =V7-W7+X7 -> 17 | Z7: =MAX(Y7,0) -> 17 | AA7: =VLOOKUP($A7,C_Sales!$A$4:$P$35,AA$1+1,0) -> 10 | AB7: =VLOOKUP($A7,'Stock Transfer'!$A$3:$AE$32,1+AA$1,0) -> 7 | AC7: =Z7-AA7+AB7 -> 14 | AD7: =MAX(AC7,0) -> 14 | AE7: =VLOOKUP($A7,C_Sales!$A$4:$P$35,AE$1+1,0) -> 1 | AF7: =VLOOKUP($A7,'Stock Transfer'!$A$3:$AE$32,1+AE$1,0) -> 5 | AG7: =AD7-AE7+AF7 -> 18 | AH7: =MAX(AG7,0) -> 18 | AI7: =VLOOKUP($A7,C_Sales!$A$4:$P$35,AI$1+1,0) -> 3 | AJ7: =VLOOKUP($A7,'Stock Transfer'!$A$3:$AE$32,1+AI$1,0) -> 4 | AK7: =AH7-AI7+AJ7 -> 19 | AL7: =MAX(AK7,0) -> 19 | AM7: =VLOOKUP($A7,C_Sales!$A$4:$P$35,AM$1+1,0) -> 3 | AN7: =VLOOKUP($A7,'Stock Transfer'!$A$3:$AE$32,1+AM$1,0) -> 6 | AO7: =AL7-AM7+AN7 -> 22 | AP7: =MAX(AO7,0) -> 22 | AQ7: =VLOOKUP($A7,C_Sales!$A$4:$P$35,AQ$1+1,0) -> 5 | AR7: =VLOOKUP($A7,'Stock Transfer'!$A$3:$AE$32,1+AQ$1,0) -> 5 | AS7: =AP7-AQ7+AR7 -> 22 | AT7: =MAX(AS7,0) -> 22 | AU7: =VLOOKUP($A7,C_Sales!$A$4:$P$35,AU$1+1,0) -> 7 | AV7: =VLOOKUP($A7,'Stock Transfer'!$A$3:$AE$32,1+AU$1,0) -> 5 | AW7: =AT7-AU7+AV7 -> 20 | AX7: =MAX(AW7,0) -> 20 | AY7: =VLOOKUP($A7,C_Sales!$A$4:$P$35,AY$1+1,0) -> 6 | AZ7: =VLOOKUP($A7,'Stock Transfer'!$A$3:$AE$32,1+AY$1,0) -> 5 | BA7: =AX7-AY7+AZ7 -> 19 | BB7: =MAX(BA7,0) -> 19 | BC7: =VLOOKUP($A7,C_Sales!$A$4:$P$35,BC$1+1,0) -> 3 | BD7: =VLOOKUP($A7,'Stock Transfer'!$A$3:$AE$32,1+BC$1,0) -> 5 | BE7: =BB7-BC7+BD7 -> 21 | BF7: =MAX(BE7,0) -> 21 | BG7: =VLOOKUP($A7,C_Sales!$A$4:$P$35,BG$1+1,0) -> 4 | BH7: =VLOOKUP($A7,'Stock Transfer'!$A$3:$AE$32,1+BG$1,0) -> 4 | BI7: =BF7-BG7+BH7 -> 21
A8: F05 | B8: =VLOOKUP($A8,'Open STK'!$A$1:$E$31,4,0) -> 13 | C8: =VLOOKUP($A8,C_Sales!$A$4:$P$35,C$1+1,0) -> 4 | D8: =VLOOKUP($A8,'Stock Transfer'!$A$3:$AE$32,1+C$1,0) -> 4 | E8: =B8-C8+D8 -> 13 | F8: =MAX(E8,0) -> 13 | G8: =VLOOKUP($A8,C_Sales!$A$4:$P$35,G$1+1,0) -> 6 | H8: =VLOOKUP($A8,'Stock Transfer'!$A$3:$AE$32,1+G$1,0) -> 6 | I8: =F8-G8+H8 -> 13 | J8: =MAX(I8,0) -> 13 | K8: =VLOOKUP($A8,C_Sales!$A$4:$P$35,K$1+1,0) -> 5 | L8: =VLOOKUP($A8,'Stock Transfer'!$A$3:$AE$32,1+K$1,0) -> 5 | M8: =J8-K8+L8 -> 13 | N8: =MAX(M8,0) -> 13 | O8: =VLOOKUP($A8,C_Sales!$A$4:$P$35,O$1+1,0) -> 5 | P8: =VLOOKUP($A8,'Stock Transfer'!$A$3:$AE$32,1+O$1,0) -> 5 | Q8: =N8-O8+P8 -> 13 | R8: =MAX(Q8,0) -> 13 | S8: =VLOOKUP($A8,C_Sales!$A$4:$P$35,S$1+1,0) -> 3 | T8: =VLOOKUP($A8,'Stock Transfer'!$A$3:$AE$32,1+S$1,0) -> 4 | U8: =R8-S8+T8 -> 14 | V8: =MAX(U8,0) -> 14 | W8: =VLOOKUP($A8,C_Sales!$A$4:$P$35,W$1+1,0) -> 2 | X8: =VLOOKUP($A8,'Stock Transfer'!$A$3:$AE$32,1+W$1,0) -> 3 | Y8: =V8-W8+X8 -> 15 | Z8: =MAX(Y8,0) -> 15 | AA8: =VLOOKUP($A8,C_Sales!$A$4:$P$35,AA$1+1,0) -> 1 | AB8: =VLOOKUP($A8,'Stock Transfer'!$A$3:$AE$32,1+AA$1,0) -> 5 | AC8: =Z8-AA8+AB8 -> 19 | AD8: =MAX(AC8,0) -> 19 | AE8: =VLOOKUP($A8,C_Sales!$A$4:$P$35,AE$1+1,0) -> 4 | AF8: =VLOOKUP($A8,'Stock Transfer'!$A$3:$AE$32,1+AE$1,0) -> 5 | AG8: =AD8-AE8+AF8 -> 20 | AH8: =MAX(AG8,0) -> 20 | AI8: =VLOOKUP($A8,C_Sales!$A$4:$P$35,AI$1+1,0) -> 7 | AJ8: =VLOOKUP($A8,'Stock Transfer'!$A$3:$AE$32,1+AI$1,0) -> 6 | AK8: =AH8-AI8+AJ8 -> 19 | AL8: =MAX(AK8,0) -> 19 | AM8: =VLOOKUP($A8,C_Sales!$A$4:$P$35,AM$1+1,0) -> 2 | AN8: =VLOOKUP($A8,'Stock Transfer'!$A$3:$AE$32,1+AM$1,0) -> 6 | AO8: =AL8-AM8+AN8 -> 23 | AP8: =MAX(AO8,0) -> 23 | AQ8: =VLOOKUP($A8,C_Sales!$A$4:$P$35,AQ$1+1,0) -> 3 | AR8: =VLOOKUP($A8,'Stock Transfer'!$A$3:$AE$32,1+AQ$1,0) -> 5 | AS8: =AP8-AQ8+AR8 -> 25 | AT8: =MAX(AS8,0) -> 25 | AU8: =VLOOKUP($A8,C_Sales!$A$4:$P$35,AU$1+1,0) -> 4 | AV8: =VLOOKUP($A8,'Stock Transfer'!$A$3:$AE$32,1+AU$1,0) -> 5 | AW8: =AT8-AU8+AV8 -> 26 | AX8: =MAX(AW8,0) -> 26 | AY8: =VLOOKUP($A8,C_Sales!$A$4:$P$35,AY$1+1,0) -> 6 | AZ8: =VLOOKUP($A8,'Stock Transfer'!$A$3:$AE$32,1+AY$1,0) -> 5 | BA8: =AX8-AY8+AZ8 -> 25 | BB8: =MAX(BA8,0) -> 25 | BC8: =VLOOKUP($A8,C_Sales!$A$4:$P$35,BC$1+1,0) -> 6 | BD8: =VLOOKUP($A8,'Stock Transfer'!$A$3:$AE$32,1+BC$1,0) -> 4 | BE8: =BB8-BC8+BD8 -> 23 | BF8: =MAX(BE8,0) -> 23 | BG8: =VLOOKUP($A8,C_Sales!$A$4:$P$35,BG$1+1,0) -> 6 | BH8: =VLOOKUP($A8,'Stock Transfer'!$A$3:$AE$32,1+BG$1,0) -> 5 | BI8: =BF8-BG8+BH8 -> 22
